Workbook

Sheet CONTROLE
A1: Basta subsitituir os rsultados de cada região do BLUES nas abas Brasil_IND_REGIAO
A2: Aba AdvBioFuels faz cálculos relacionados à biomcombustíveis avançados
A3: Energia Final_MSG e Emisões MSG são as planilhas que agregam as informações do BLUES. Elas que devem ser checadas para garantir que estão pegando os dados do BLUES de forma correta
A5: INDICAÇÕES
A6: VA | B6: Copiar e colar novos os valores de VA enviados por FIPE na aba VA. A planilha COEF atualizará-se automáticamente
A7: COEF | B7: Calculados em função da aba VA e da aba WIOT BR 2009
A8: ENERGIA FINAL_MSG | B8: Desagregação de valores por atividade da FIPE, a partir dos resultados do MESSAGE
A9: EMISSÕES_MSG | B9: Desagregação de valores por atividade da FIPE, a partir dos resultados do MESSAGE
A10: INDICADOR ENERGIA FINAL | B10: Calculados em função da aba VA e ENERGIA FINAL | F10: > Esses vão para FIPE
A11: INDICADOR EMISSÕES | B11: Calculados em função da aba VA e EMISSÕES | F11: > Esses vão para FIPE
A16: EQUIVALÊNCIAS
A18: 1 | B18: MWyr | C18: igual a | D18: 8760 | E18: MWh
D19: =$D$18*1000*(8.598*10^(-5))/1000 -> 0.7531848 | E19: ktep
A21: 1 | B21: ktep | C21: igual a | D21: =1/D19 -> 1.3276954 | E21: MWyr
A24: 1 | B24: t de bagaço | C24: igual a | D24: 0.213 | E24: tep
A25: 1 | B25: kt de bagaço | C25: igual a | D25: =$D$24*1000 -> 213 | E25: tep
D26: =D25/1000 -> 0.213 | E26: ktep
A30: Considerações para o projeto Pernambuco-GIZ (Ago/2021)
A31: Setores
A32: Serviços | B32: Todos os serviços têm a mesma intensidade energética, dado que não temos discretização no BLUES
A33: Transportes | B33: Retiramos os veículos particulares (carros e motos), e deixamos o restante
A34: Fabricação de biocombustíveis | B34: Alocação das emissões negativas obtidas na produção de biocombustíveis aqui
A35: Indústria | B35: Foi feita pelo Régis Rathmann, exogenamente a essa planilha
A38: Combustíveis
A39: Combustíveis avançados: | B39: Alocados em "Outros (liquor negro, biodiesel, nuclear)"
A40: Biomassa primária | B40: Alocada em "Lenha"
A42: Planilhas
A43: AdvBioFuels | B43: Calcula o FE ponderados dos biocombustíveis avançados, a porcentagem de biocombustíveis avançados em relação ao total, o consumo e emissão dos setores de transportes do EFES.
A44: Brasil_Emissions | B44: Recalcula as emissões setoriais da região Brasil com os novos FE da planilha AdvBioFuels
A47: ToDo:
A48: Descontar o combustível dos veículos híbridos particulares (carros). Nessa versão não está entrando, então não descontei.

Sheet VA
A1: No. Atividades | C1: Classes e atividades MESSAGE | E1: Valor adicionado R$ Milhões de 2013
E2: 2010 | F2: =E2+5 -> 2015 | G2: =F2+5 -> 2020 | H2: =G2+5 -> 2025 | I2: =H2+5 -> 2030 | J2: =I2+5 -> 2035 | K2: =J2+5 -> 2040 | L2: =K2+5 -> 2045 | M2: =L2+5 -> 2050
A4: 1 | B4: Agricultura, silvicultura, exploração florestal | C4: AGR | D4: Agriculture | F4: 189451.26 | G4: 190862.2 | H4: 214360.92 | I4: 236542.4 | J4: 259823.12 | K4: 282284.05 | L4: 307161.28 | M4: 334345.94
A5: =A4+1 -> 2 | B5: Pecuária, inclusive o apoio à pecuária | C5: AGR | D5: Agriculture | F5: 83846.245 | G5: 80597.153 | H5: 90124.705 | I5: 98545.619 | J5: 107041.94 | K5: 114737.18 | L5: 123147.25 | M5: 132144.17
A6: =A5+1 -> 3 | B6: Produção florestal; pesca e aquicultura | C6: AGR | D6: Agriculture | F6: 27099.898 | G6: 26982.68 | H6: 30116.539 | I6: 33246.963 | J6: 36706.168 | K6: 40265.2 | L6: 44346.639 | M6: 48945.743
A7: =A6+1 -> 4 | B7: Extração de carvão mineral e de minerais não-metálicos | C7: OI | D7: Mining | F7: 10451.705 | G7: 9456.9822 | H7: 11687.898 | I7: 13374.586 | J7: 15083.99 | K7: 16763.017 | L7: 18626.955 | M7: 20675.887
A8: =A7+1 -> 5 | B8: Extração de petróleo e gás, inclusive as atividades de apoio | C8: OIL | D8: Oil and Gas | F8: 86826.567 | G8: 85441.509 | H8: 97123.482 | I8: 107932.32 | J8: 119563.49 | K8: 131262.75 | L8: 144612.58 | M8: 159652.41 | O8: 2010 | P8: =O8+5 -> 2015 | Q8: =P8+5 -> 2020 | R8: =Q8+5 -> 2025 | S8: =R8+5 -> 2030 | T8: =S8+5 -> 2035 | U8: =T8+5 -> 2040 | V8: =U8+5 -> 2045 | W8: =V8+5 -> 2050
A9: =A8+1 -> 6 | B9: Extração de minério de ferro, inclusive beneficiamentos e a aglomeração | C9: OI | D9: Mining | F9: 27778.203 | G9: 27822.256 | H9: 30862.657 | I9: 33689.719 | J9: 36603.6 | K9: 39335.91 | L9: 42292.064 | M9: 45450.766 | N9: Agriculture | P9: =SUMIFS(OFFSET(E2,2,(P$8-$O$8)/5,66,1),$D$4:$D$69,$N9) -> 300397.4
A10: =A9+1 -> 7 | B10: Extração de minerais metálicos não-ferrosos, inclusive beneficiamentos | C10: OI | D10: Mining | F10: 5539.5361 | G10: 5518.5979 | H10: 6409.3858 | I10: 7178.2564 | J10: 7967.5749 | K10: 8716.1638 | L10: 9538.32 | M10: 10426.933
A11: =A10+1 -> 8 | B11: Abate e produtos de carne, inclusive os produtos do laticínio e da pesca | C11: FB | D11: Food and Beverage | F11: 50931.506 | G11: 52547.769 | H11: 60495.511 | I11: 68814.728 | J11: 77886.696 | K11: 86984.474 | L11: 97283.968 | M11: 108763.66
A12: =A11+1 -> 9 | B12: Fabricação e refino de açúcar | C12: FB | D12: Food and Beverage | F12: 9352.2236 | G12: 9740.0835 | H12: 11618.539 | I12: 13333.615 | J12: 15143.316 | K12: 16924.563 | L12: 18920.516 | M12: 21125.466
A13: =A12+1 -> 10 | B13: Outros produtos alimentares | C13: FB | D13: Food and Beverage | F13: 58844.987 | G13: 59868.557 | H13: 68159.46 | I13: 76784.309 | J13: 86144.39 | K13: 95458.691 | L13: 105986.54 | M13: 117698.42
A14: =A13+1 -> 11 | B14: Fabricação de bebidas | C14: FB | D14: Food and Beverage | F14: 27585.282 | G14: 27518.762 | H14: 31101.671 | I14: 34733.358 | J14: 38642.179 | K14: 42510.904 | L14: 46888.353 | M14: 51761.406
A15: =A14+1 -> 12 | B15: Fabricação de produtos do fumo | C15: FB | D15: Food and Beverage | F15: 4904.7446 | G15: 4933.9533 | H15: 5631.7984 | I15: 6309.9033 | J15: 7043.7 | K15: 7783.9359 | L15: 8623.0833 | M15: 9561.2998
A16: =A15+1 -> 13 | B16: Fabricação de produtos têxteis | C16: TX | D16: Textile | F16: 16908.679 | G16: 16751.085 | H16: 19853.336 | I16: 23049.795 | J16: 26579.988 | K16: 30197.908 | L16: 34353.82 | M16: 39055.019
A17: =A16+1 -> 14 | B17: Confecção de artefatos do vestuário e acessórios | C17: TX | D17: Textile | F17: 30655.372 | G17: 31240.889 | H17: 36182.408 | I17: 41576.909 | J17: 47570.974 | K17: 53711.862 | L17: 60729.337 | M17: 68620.22
A18: =A17+1 -> 15 | B18: Fabricação de calçados e de artefatos de couro | C18: TX | D18: Textile | F18: 16111.08 | G18: 16352.381 | H18: 19019.71 | I18: 21631.993 | J18: 24430.52 | K18: 27198.461 | L18: 30322.072 | M18: 33788.522
A19: =A18+1 -> 16 | B19: Fabricação de produtos da madeira | C19: OI | D19: Other industries | F19: 11851.893 | G19: 11404.017 | H19: 13624.389 | I19: 15448.242 | J19: 17311.697 | K19: 19121.807 | L19: 21132.743 | M19: 23340.579
A20: =A19+1 -> 17 | B20: Fabricação de celulose, papel e produtos de papel | C20: OI | D20: Paper | F20: 27915.295 | G20: 27571.279 | H20: 31650.857 | I20: 35219.802 | J20: 38880.655 | K20: 42338.087 | L20: 46159.325 | M20: 50315.157
A21: =A20+1 -> 18 | B21: Impressão e reprodução de gravações | C21: OI | D21: Other industries | F21: 9723.8195 | G21: 8619.73 | H21: 9184.761 | I21: 9526.1691 | J21: 9809.129 | K21: 9966.6986 | L21: 10140.323 | M21: 10314.737
... A69: =A68+1 -> 66 | B69: Organizações associativas e outros serviços pessoais | C69: BL | D69: Buildings and services | F69: 153055.74 | G69: 157230.92 | H69: 180680.38 | I69: 205991.87 | J69: 234045.85 | K69: 262488.2 | L69: 294878.98 | M69: 331082.27

Sheet COEF
A1: No. Atividades | C1: Classes e atividades MESSAGE | E1: Valor adicionado R$ Milhões de 2013 | N1: Fator de peso relativo setorial | O1: Tipo de COEF share | P1: Coeficientes para desagregar valores de energia final do MSG
E2: 2010 | F2: =E2+5 -> 2015 | G2: =F2+5 -> 2020 | H2: =G2+5 -> 2025 | I2: =H2+5 -> 2030 | J2: =I2+5 -> 2035 | K2: =J2+5 -> 2040 | L2: =K2+5 -> 2045 | M2: =L2+5 -> 2050 | P2: 2010 | Q2: =P2+5 -> 2015 | R2: =Q2+5 -> 2020 | S2: =R2+5 -> 2025 | T2: =S2+5 -> 2030 | U2: =T2+5 -> 2035 | V2: =U2+5 -> 2040 | W2: =V2+5 -> 2045 | X2: =W2+5 -> 2050
A4: 1 | B4: Agricultura, silvicultura, exploração florestal | C4: AGR | D4: Agriculture | E4: =VA!E4 -> 0 | F4: =VA!F4 -> 189451.26 | G4: =VA!G4 -> 190862.2 | H4: =VA!H4 -> 214360.92 | I4: =VA!I4 -> 236542.4 | J4: =VA!J4 -> 259823.12 | K4: =VA!K4 -> 282284.05 | L4: =VA!L4 -> 307161.28 | M4: =VA!M4 -> 334345.94 | N4: 1 | O4: share VA setor | P4: =$N4*(E4/SUM(E$4:E$6)) -> #DIV/0! | Q4: =$N4*(F4/SUM(F$4:F$6)) -> 0.63066877 | R4: =$N4*(G4/SUM(G$4:G$6)) -> 0.63952855 | S4: =$N4*(H4/SUM(H$4:H$6)) -> 0.64064416 | T4: =$N4*(I4/SUM(I$4:I$6)) -> 0.64219368 | U4: =$N4*(J4/SUM(J$4:J$6)) -> 0.64380982 | V4: =$N4*(K4/SUM(K$4:K$6)) -> 0.64553581 | W4: =$N4*(L4/SUM(L$4:L$6)) -> 0.64712511 | X4: =$N4*(M4/SUM(M$4:M$6)) -> 0.64866644
A5: =A4+1 -> 2 | B5: Pecuária, inclusive o apoio à pecuária | C5: AGR | D5: Agriculture | E5: =VA!E5 -> 0 | F5: =VA!F5 -> 83846.245 | G5: =VA!G5 -> 80597.153 | H5: =VA!H5 -> 90124.705 | I5: =VA!I5 -> 98545.619 | J5: =VA!J5 -> 107041.94 | K5: =VA!K5 -> 114737.18 | L5: =VA!L5 -> 123147.25 | M5: =VA!M5 -> 132144.17 | N5: 1 | O5: share VA setor | P5: =$N5*(E5/SUM(E$4:E$6)) -> #DIV/0! | Q5: =$N5*(F5/SUM(F$4:F$6)) -> 0.27911774 | R5: =$N5*(G5/SUM(G$4:G$6)) -> 0.27005966 | S5: =$N5*(H5/SUM(H$4:H$6)) -> 0.26934884 | T5: =$N5*(I5/SUM(I$4:I$6)) -> 0.26754347 | U5: =$N5*(J5/SUM(J$4:J$6)) -> 0.2652368 | V5: =$N5*(K5/SUM(K$4:K$6)) -> 0.2623845 | W5: =$N5*(L5/SUM(L$4:L$6)) -> 0.25944572 | X5: =$N5*(M5/SUM(M$4:M$6)) -> 0.25637365
A6: =A5+1 -> 3 | B6: Produção florestal; pesca e aquicultura | C6: AGR | D6: Agriculture | E6: =VA!E6 -> 0 | F6: =VA!F6 -> 27099.898 | G6: =VA!G6 -> 26982.68 | H6: =VA!H6 -> 30116.539 | I6: =VA!I6 -> 33246.963 | J6: =VA!J6 -> 36706.168 | K6: =VA!K6 -> 40265.2 | L6: =VA!L6 -> 44346.639 | M6: =VA!M6 -> 48945.743 | N6: 1 | O6: share VA setor | P6: =$N6*(E6/SUM(E$4:E$6)) -> #DIV/0! | Q6: =$N6*(F6/SUM(F$4:F$6)) -> 0.09021349 | R6: =$N6*(G6/SUM(G$4:G$6)) -> 0.090411796 | S6: =$N6*(H6/SUM(H$4:H$6)) -> 0.090007004 | T6: =$N6*(I6/SUM(I$4:I$6)) -> 0.090262843 | U6: =$N6*(J6/SUM(J$4:J$6)) -> 0.090953381 | V6: =$N6*(K6/SUM(K$4:K$6)) -> 0.092079694 | W6: =$N6*(L6/SUM(L$4:L$6)) -> 0.093429171 | X6: =$N6*(M6/SUM(M$4:M$6)) -> 0.094959912
A7: =A6+1 -> 4 | B7: Extração de carvão mineral e de minerais não-metálicos | C7: OI | D7: Mining | E7: =VA!E7 -> 0 | F7: =VA!F7 -> 10451.705 | G7: =VA!G7 -> 9456.9822 | H7: =VA!H7 -> 11687.898 | I7: =VA!I7 -> 13374.586 | J7: =VA!J7 -> 15083.99 | K7: =VA!K7 -> 16763.017 | L7: =VA!L7 -> 18626.955 | M7: =VA!M7 -> 20675.887
A8: =A7+1 -> 5 | B8: Extração de petróleo e gás, inclusive as atividades de apoio | C8: OIL | D8: Oil and Gas | E8: =VA!E8 -> 0 | F8: =VA!F8 -> 86826.567 | G8: =VA!G8 -> 85441.509 | H8: =VA!H8 -> 97123.482 | I8: =VA!I8 -> 107932.32 | J8: =VA!J8 -> 119563.49 | K8: =VA!K8 -> 131262.75 | L8: =VA!L8 -> 144612.58 | M8: =VA!M8 -> 159652.41 | N8: 1 | O8: MSG | P8: =$N8*(E8/SUM(E$8)) -> #DIV/0! | Q8: =$N8*(F8/SUM(F$8)) -> 1 | R8: =$N8*(G8/SUM(G$8)) -> 1 | S8: =$N8*(H8/SUM(H$8)) -> 1 | T8: =$N8*(I8/SUM(I$8)) -> 1 | U8: =$N8*(J8/SUM(J$8)) -> 1 | V8: =$N8*(K8/SUM(K$8)) -> 1 | W8: =$N8*(L8/SUM(L$8)) -> 1 | X8: =$N8*(M8/SUM(M$8)) -> 1
A9: =A8+1 -> 6 | B9: Extração de minério de ferro, inclusive beneficiamentos e a aglomeração | C9: OI | D9: Mining | E9: =VA!E9 -> 0 | F9: =VA!F9 -> 27778.203 | G9: =VA!G9 -> 27822.256 | H9: =VA!H9 -> 30862.657 | I9: =VA!I9 -> 33689.719 | J9: =VA!J9 -> 36603.6 | K9: =VA!K9 -> 39335.91 | L9: =VA!L9 -> 42292.064 | M9: =VA!M9 -> 45450.766 | N9: 1 | O9: share VA setor | P9: =$N9*(E9/SUM(E$9:E$10)) -> #DIV/0! | Q9: =$N9*(F9/SUM(F$9:F$10)) -> 0.83373614 | R9: =$N9*(G9/SUM(G$9:G$10)) -> 0.83447941 | S9: =$N9*(H9/SUM(H$9:H$10)) -> 0.82803771 | T9: =$N9*(I9/SUM(I$9:I$10)) -> 0.82435498 | U9: =$N9*(J9/SUM(J$9:J$10)) -> 0.82123929 | V9: =$N9*(K9/SUM(K$9:K$10)) -> 0.81861004 | W9: =$N9*(L9/SUM(L$9:L$10)) -> 0.81597049 | X9: =$N9*(M9/SUM(M$9:M$10)) -> 0.81339723
A10: =A9+1 -> 7 | B10: Extração de minerais metálicos não-ferrosos, inclusive beneficiamentos | C10: OI | D10: Mining | E10: =VA!E10 -> 0 | F10: =VA!F10 -> 5539.5361 | G10: =VA!G10 -> 5518.5979 | H10: =VA!H10 -> 6409.3858 | I10: =VA!I10 -> 7178.2564 | J10: =VA!J10 -> 7967.5749 | K10: =VA!K10 -> 8716.1638 | L10: =VA!L10 -> 9538.32 | M10: =VA!M10 -> 10426.933 | N10: 1 | O10: share VA setor | P10: =$N10*(E10/SUM(E$9:E$10)) -> #DIV/0! | Q10: =$N10*(F10/SUM(F$9:F$10)) -> 0.16626386 | R10: =$N10*(G10/SUM(G$9:G$10)) -> 0.16552059 | S10: =$N10*(H10/SUM(H$9:H$10)) -> 0.17196229 | T10: =$N10*(I10/SUM(I$9:I$10)) -> 0.17564502 | U10: =$N10*(J10/SUM(J$9:J$10)) -> 0.17876071 | V10: =$N10*(K10/SUM(K$9:K$10)) -> 0.18138996 | W10: =$N10*(L10/SUM(L$9:L$10)) -> 0.18402951 | X10: =$N10*(M10/SUM(M$9:M$10)) -> 0.18660277
A11: =A10+1 -> 8 | B11: Abate e produtos de carne, inclusive os produtos do laticínio e da pesca | C11: FB | D11: Food and Beverage | E11: =VA!E11 -> 0 | F11: =VA!F11 -> 50931.506 | G11: =VA!G11 -> 52547.769 | H11: =VA!H11 -> 60495.511 | I11: =VA!I11 -> 68814.728 | J11: =VA!J11 -> 77886.696 | K11: =VA!K11 -> 86984.474 | L11: =VA!L11 -> 97283.968 | M11: =VA!M11 -> 108763.66 | N11: 1 | O11: share VA setor | P11: =$N11*(E11/SUM(E$11:E$15)) -> #DIV/0! | Q11: =$N11*(F11/SUM(F$11:F$15)) -> 0.33591827 | R11: =$N11*(G11/SUM(G$11:G$15)) -> 0.33987495 | S11: =$N11*(H11/SUM(H$11:H$15)) -> 0.34176907 | T11: =$N11*(I11/SUM(I$11:I$15)) -> 0.34411508 | U11: =$N11*(J11/SUM(J$11:J$15)) -> 0.34637819 | V11: =$N11*(K11/SUM(K$11:K$15)) -> 0.34840815 | W11: =$N11*(L11/SUM(L$11:L$15)) -> 0.35031727 | X11: =$N11*(M11/SUM(M$11:M$15)) -> 0.35208821
A12: =A11+1 -> 9 | B12: Fabricação e refino de açúcar | C12: FB | D12: Food and Beverage | E12: =VA!E12 -> 0 | F12: =VA!F12 -> 9352.2236 | G12: =VA!G12 -> 9740.0835 | H12: =VA!H12 -> 11618.539 | I12: =VA!I12 -> 13333.615 | J12: =VA!J12 -> 15143.316 | K12: =VA!K12 -> 16924.563 | L12: =VA!L12 -> 18920.516 | M12: =VA!M12 -> 21125.466 | N12: 1 | O12: share VA setor | P12: =$N12*(E12/SUM(E$11:E$15)) -> #DIV/0! | Q12: =$N12*(F12/SUM(F$11:F$15)) -> 0.061682504 | R12: =$N12*(G12/SUM(G$11:G$15)) -> 0.062998115 | S12: =$N12*(H12/SUM(H$11:H$15)) -> 0.065638875 | T12: =$N12*(I12/SUM(I$11:I$15)) -> 0.066676106 | U12: =$N12*(J12/SUM(J$11:J$15)) -> 0.067345446 | V12: =$N12*(K12/SUM(K$11:K$15)) -> 0.067789749 | W12: =$N12*(L12/SUM(L$11:L$15)) -> 0.068132329 | X12: =$N12*(M12/SUM(M$11:M$15)) -> 0.068387068
A13: =A12+1 -> 10 | B13: Outros produtos alimentares | C13: FB | D13: Food and Beverage | E13: =VA!E13 -> 0 | F13: =VA!F13 -> 58844.987 | G13: =VA!G13 -> 59868.557 | H13: =VA!H13 -> 68159.46 | I13: =VA!I13 -> 76784.309 | J13: =VA!J13 -> 86144.39 | K13: =VA!K13 -> 95458.691 | L13: =VA!L13 -> 105986.54 | M13: =VA!M13 -> 117698.42 | N13: 1 | O13: share VA setor | P13: =$N13*(E13/SUM(E$11:E$15)) -> #DIV/0! | Q13: =$N13*(F13/SUM(F$11:F$15)) -> 0.38811156 | R13: =$N13*(G13/SUM(G$11:G$15)) -> 0.38722525 | S13: =$N13*(H13/SUM(H$11:H$15)) -> 0.38506651 | T13: =$N13*(I13/SUM(I$11:I$15)) -> 0.38396779 | U13: =$N13*(J13/SUM(J$11:J$15)) -> 0.38310185 | V13: =$N13*(K13/SUM(K$11:K$15)) -> 0.38235083 | W13: =$N13*(L13/SUM(L$11:L$15)) -> 0.38165503 | X13: =$N13*(M13/SUM(M$11:M$15)) -> 0.38101171
A14: =A13+1 -> 11 | B14: Fabricação de bebidas | C14: FB | D14: Food and Beverage | E14: =VA!E14 -> 0 | F14: =VA!F14 -> 27585.282 | G14: =VA!G14 -> 27518.762 | H14: =VA!H14 -> 31101.671 | I14: =VA!I14 -> 34733.358 | J14: =VA!J14 -> 38642.179 | K14: =VA!K14 -> 42510.904 | L14: =VA!L14 -> 46888.353 | M14: =VA!M14 -> 51761.406 | N14: 1 | O14: share VA setor | P14: =$N14*(E14/SUM(E$11:E$15)) -> #DIV/0! | Q14: =$N14*(F14/SUM(F$11:F$15)) -> 0.18193847 | R14: =$N14*(G14/SUM(G$11:G$15)) -> 0.17798925 | S14: =$N14*(H14/SUM(H$11:H$15)) -> 0.17570873 | T14: =$N14*(I14/SUM(I$11:I$15)) -> 0.17368771 | U14: =$N14*(J14/SUM(J$11:J$15)) -> 0.17184973 | V14: =$N14*(K14/SUM(K$11:K$15)) -> 0.17027344 | W14: =$N14*(L14/SUM(L$11:L$15)) -> 0.16884385 | X14: =$N14*(M14/SUM(M$11:M$15)) -> 0.16756131
A15: =A14+1 -> 12 | B15: Fabricação de produtos do fumo | C15: FB | D15: Food and Beverage | E15: =VA!E15 -> 0 | F15: =VA!F15 -> 4904.7446 | G15: =VA!G15 -> 4933.9533 | H15: =VA!H15 -> 5631.7984 | I15: =VA!I15 -> 6309.9033 | J15: =VA!J15 -> 7043.7 | K15: =VA!K15 -> 7783.9359 | L15: =VA!L15 -> 8623.0833 | M15: =VA!M15 -> 9561.2998 | N15: 1 | O15: share VA setor | P15: =$N15*(E15/SUM(E$11:E$15)) -> #DIV/0! | Q15: =$N15*(F15/SUM(F$11:F$15)) -> 0.032349197 | R15: =$N15*(G15/SUM(G$11:G$15)) -> 0.031912433 | S15: =$N15*(H15/SUM(H$11:H$15)) -> 0.031816816 | T15: =$N15*(I15/SUM(I$11:I$15)) -> 0.031553316 | U15: =$N15*(J15/SUM(J$11:J$15)) -> 0.031324785 | V15: =$N15*(K15/SUM(K$11:K$15)) -> 0.031177825 | W15: =$N15*(L15/SUM(L$11:L$15)) -> 0.031051519 | X15: =$N15*(M15/SUM(M$11:M$15)) -> 0.030951707
A16: =A15+1 -> 13 | B16: Fabricação de produtos têxteis | C16: TX | D16: Textile | E16: =VA!E16 -> 0 | F16: =VA!F16 -> 16908.679 | G16: =VA!G16 -> 16751.085 | H16: =VA!H16 -> 19853.336 | I16: =VA!I16 -> 23049.795 | J16: =VA!J16 -> 26579.988 | K16: =VA!K16 -> 30197.908 | L16: =VA!L16 -> 34353.82 | M16: =VA!M16 -> 39055.019 | N16: 1 | O16: share VA setor | P16: =$N16*(E16/SUM(E$16:E$18)) -> #DIV/0! | Q16: =$N16*(F16/SUM(F$16:F$18)) -> 0.26554604 | R16: =$N16*(G16/SUM(G$16:G$18)) -> 0.26033496 | S16: =$N16*(H16/SUM(H$16:H$18)) -> 0.26451556 | T16: =$N16*(I16/SUM(I$16:I$18)) -> 0.26721706 | U16: =$N16*(J16/SUM(J$16:J$18)) -> 0.26962456 | V16: =$N16*(K16/SUM(K$16:K$18)) -> 0.27178822 | W16: =$N16*(L16/SUM(L$16:L$18)) -> 0.27394249 | X16: =$N16*(M16/SUM(M$16:M$18)) -> 0.27607791
A17: =A16+1 -> 14 | B17: Confecção de artefatos do vestuário e acessórios | C17: TX | D17: Textile | E17: =VA!E17 -> 0 | F17: =VA!F17 -> 30655.372 | G17: =VA!G17 -> 31240.889 | H17: =VA!H17 -> 36182.408 | I17: =VA!I17 -> 41576.909 | J17: =VA!J17 -> 47570.974 | K17: =VA!K17 -> 53711.862 | L17: =VA!L17 -> 60729.337 | M17: =VA!M17 -> 68620.22 | N17: 1 | O17: share VA setor | P17: =$N17*(E17/SUM(E$16:E$18)) -> #DIV/0! | Q17: =$N17*(F17/SUM(F$16:F$18)) -> 0.48143398 | R17: =$N17*(G17/SUM(G$16:G$18)) -> 0.48552649 | S17: =$N17*(H17/SUM(H$16:H$18)) -> 0.48207567 | T17: =$N17*(I17/SUM(I$16:I$18)) -> 0.48200251 | U17: =$N17*(J17/SUM(J$16:J$18)) -> 0.48255487 | V17: =$N17*(K17/SUM(K$16:K$18)) -> 0.48341929 | W17: =$N17*(L17/SUM(L$16:L$18)) -> 0.48426479 | X17: =$N17*(M17/SUM(M$16:M$18)) -> 0.48507278
A18: =A17+1 -> 15 | B18: Fabricação de calçados e de artefatos de couro | C18: TX | D18: Textile | E18: =VA!E18 -> 0 | F18: =VA!F18 -> 16111.08 | G18: =VA!G18 -> 16352.381 | H18: =VA!H18 -> 19019.71 | I18: =VA!I18 -> 21631.993 | J18: =VA!J18 -> 24430.52 | K18: =VA!K18 -> 27198.461 | L18: =VA!L18 -> 30322.072 | M18: =VA!M18 -> 33788.522 | N18: 1 | O18: share VA setor | P18: =$N18*(E18/SUM(E$16:E$18)) -> #DIV/0! | Q18: =$N18*(F18/SUM(F$16:F$18)) -> 0.25301998 | R18: =$N18*(G18/SUM(G$16:G$18)) -> 0.25413855 | S18: =$N18*(H18/SUM(H$16:H$18)) -> 0.25340877 | T18: =$N18*(I18/SUM(I$16:I$18)) -> 0.25078043 | U18: =$N18*(J18/SUM(J$16:J$18)) -> 0.24782057 | V18: =$N18*(K18/SUM(K$16:K$18)) -> 0.24479249 | W18: =$N18*(L18/SUM(L$16:L$18)) -> 0.24179272 | X18: =$N18*(M18/SUM(M$16:M$18)) -> 0.23884931
A19: =A18+1 -> 16 | B19: Fabricação de produtos da madeira | C19: OI | D19: Other industries | E19: =VA!E19 -> 0 | F19: =VA!F19 -> 11851.893 | G19: =VA!G19 -> 11404.017 | H19: =VA!H19 -> 13624.389 | I19: =VA!I19 -> 15448.242 | J19: =VA!J19 -> 17311.697 | K19: =VA!K19 -> 19121.807 | L19: =VA!L19 -> 21132.743 | M19: =VA!M19 -> 23340.579 | N19: =#REF! -> #REF! | O19: share TJ intrasetorial | P19: =$N19*1 -> #REF! | Q19: =$N19*1 -> #REF! | R19: =$N19*1 -> #REF! | S19: =$N19*1 -> #REF! | T19: =$N19*1 -> #REF! | U19: =$N19*1 -> #REF! | V19: =$N19*1 -> #REF! | W19: =$N19*1 -> #REF! | X19: =$N19*1 -> #REF!
A20: =A19+1 -> 17 | B20: Fabricação de celulose, papel e produtos de papel | C20: OI | D20: Paper | E20: =VA!E20 -> 0 | F20: =VA!F20 -> 27915.295 | G20: =VA!G20 -> 27571.279 | H20: =VA!H20 -> 31650.857 | I20: =VA!I20 -> 35219.802 | J20: =VA!J20 -> 38880.655 | K20: =VA!K20 -> 42338.087 | L20: =VA!L20 -> 46159.325 | M20: =VA!M20 -> 50315.157 | N20: 1 | O20: MSG | P20: =$N20*1 -> 1 | Q20: =$N20*1 -> 1 | R20: =$N20*1 -> 1 | S20: =$N20*1 -> 1 | T20: =$N20*1 -> 1 | U20: =$N20*1 -> 1 | V20: =$N20*1 -> 1 | W20: =$N20*1 -> 1 | X20: =$N20*1 -> 1
A21: =A20+1 -> 18 | B21: Impressão e reprodução de gravações | C21: OI | D21: Other industries | E21: =VA!E21 -> 0 | F21: =VA!F21 -> 9723.8195 | G21: =VA!G21 -> 8619.73 | H21: =VA!H21 -> 9184.761 | I21: =VA!I21 -> 9526.1691 | J21: =VA!J21 -> 9809.129 | K21: =VA!K21 -> 9966.6986 | L21: =VA!L21 -> 10140.323 | M21: =VA!M21 -> 10314.737 | N21: =#REF! -> #REF! | O21: share TJ intrasetorial | P21: =$N21*E21/(E10+E21+E24) -> #REF! | Q21: =$N21*F21/(F10+F21+F24) -> #REF! | R21: =$N21*G21/(G10+G21+G24) -> #REF! | S21: =$N21*H21/(H10+H21+H24) -> #REF! | T21: =$N21*I21/(I10+I21+I24) -> #REF! | U21: =$N21*J21/(J10+J21+J24) -> #REF! | V21: =$N21*K21/(K10+K21+K24) -> #REF! | W21: =$N21*L21/(L10+L21+L24) -> #REF! | X21: =$N21*M21/(M10+M21+M24) -> #REF!
A22: =A21+1 -> 19 | B22: Refino de petróleo e coquerias | C22: REF | D22: Refinery | E22: =VA!E22 -> 0 | F22: =VA!F22 -> 78545.447 | G22: =VA!G22 -> 76587.798 | H22: =VA!H22 -> 85304.094 | I22: =VA!I22 -> 93307.415 | J22: =VA!J22 -> 101682.32 | K22: =VA!K22 -> 109672.61 | L22: =VA!L22 -> 118530.88 | M22: =VA!M22 -> 128157.32 | N22: 1 | O22: MSG | P22: =$N22*(E22/SUM(E$22)) -> #DIV/0! | Q22: =$N22*(F22/SUM(F$22)) -> 1 | R22: =$N22*(G22/SUM(G$22)) -> 1 | S22: =$N22*(H22/SUM(H$22)) -> 1 | T22: =$N22*(I22/SUM(I$22)) -> 1 | U22: =$N22*(J22/SUM(J$22)) -> 1 | V22: =$N22*(K22/SUM(K$22)) -> 1 | W22: =$N22*(L22/SUM(L$22)) -> 1 | X22: =$N22*(M22/SUM(M$22)) -> 1
A23: =A22+1 -> 20 | B23: Fabricação de biocombustíveis | C23: BIO | D23: Biofuels | E23: =VA!E23 -> 0 | F23: =VA!F23 -> 10422.474 | G23: =VA!G23 -> 10352.108 | H23: =VA!H23 -> 11718.934 | I23: =VA!I23 -> 13070.826 | J23: =VA!J23 -> 14535.86 | K23: =VA!K23 -> 15986.175 | L23: =VA!L23 -> 17632.341 | M23: =VA!M23 -> 19467.227 | N23: 1 | O23: MSG | P23: =$N23*(E23/SUM(E$23)) -> #DIV/0! | Q23: =$N23*(F23/SUM(F$23)) -> 1 | R23: =$N23*(G23/SUM(G$23)) -> 1 | S23: =$N23*(H23/SUM(H$23)) -> 1 | T23: =$N23*(I23/SUM(I$23)) -> 1 | U23: =$N23*(J23/SUM(J$23)) -> 1 | V23: =$N23*(K23/SUM(K$23)) -> 1 | W23: =$N23*(L23/SUM(L$23)) -> 1 | X23: =$N23*(M23/SUM(M$23)) -> 1
A24: =A23+1 -> 21 | B24: Fabricação de químicos orgânicos e inorgânicos, resinas e elastômeros | C24: CH | D24: Chemical | E24: =VA!E24 -> 0 | F24: =VA!F24 -> 33636.274 | G24: =VA!G24 -> 31503.721 | H24: =VA!H24 -> 36310.702 | I24: =VA!I24 -> 40287.55 | J24: =VA!J24 -> 44275.276 | K24: =VA!K24 -> 47931.075 | L24: =VA!L24 -> 51917.706 | M24: =VA!M24 -> 56184.437 | N24: =#REF! -> #REF! | O24: share TJ intrasetorial | P24: =$N24*(E24/SUM(E$24:E$27)) -> #REF! | Q24: =$N24*(F24/SUM(F$24:F$27)) -> #REF! | R24: =$N24*(G24/SUM(G$24:G$27)) -> #REF! | S24: =$N24*(H24/SUM(H$24:H$27)) -> #REF! | T24: =$N24*(I24/SUM(I$24:I$27)) -> #REF! | U24: =$N24*(J24/SUM(J$24:J$27)) -> #REF! | V24: =$N24*(K24/SUM(K$24:K$27)) -> #REF! | W24: =$N24*(L24/SUM(L$24:L$27)) -> #REF! | X24: =$N24*(M24/SUM(M$24:M$27)) -> #REF!
A25: =A24+1 -> 22 | B25: Fabricação de defensivos, desinfestantes, tintas e químicos diversos | C25: CH | D25: Chemical | E25: =VA!E25 -> 0 | F25: =VA!F25 -> 19698.592 | G25: =VA!G25 -> 18266.017 | H25: =VA!H25 -> 21572.605 | I25: =VA!I25 -> 24281.442 | J25: =VA!J25 -> 27016.174 | K25: =VA!K25 -> 29592.465 | L25: =VA!L25 -> 32423.756 | M25: =VA!M25 -> 35491.228 | N25: =#REF! -> #REF! | O25: share TJ intrasetorial | P25: =$N25*(E25/SUM(E$24:E$27)) -> #REF! | Q25: =$N25*(F25/SUM(F$24:F$27)) -> #REF! | R25: =$N25*(G25/SUM(G$24:G$27)) -> #REF! | S25: =$N25*(H25/SUM(H$24:H$27)) -> #REF! | T25: =$N25*(I25/SUM(I$24:I$27)) -> #REF! | U25: =$N25*(J25/SUM(J$24:J$27)) -> #REF! | V25: =$N25*(K25/SUM(K$24:K$27)) -> #REF! | W25: =$N25*(L25/SUM(L$24:L$27)) -> #REF! | X25: =$N25*(M25/SUM(M$24:M$27)) -> #REF!
A26: =A25+1 -> 23 | B26: Fabricação de produtos de limpeza, cosméticos/perfumaria e higiene pessoal | C26: CH | D26: Chemical | E26: =VA!E26 -> 0 | F26: =VA!F26 -> 10900.907 | G26: =VA!G26 -> 10978.213 | H26: =VA!H26 -> 12579.33 | I26: =VA!I26 -> 14253.463 | J26: =VA!J26 -> 16071.05 | K26: =VA!K26 -> 17879.44 | L26: =VA!L26 -> 19920.02 | M26: =VA!M26 -> 22184.863 | N26: =#REF! -> #REF! | O26: share TJ intrasetorial | P26: =$N26*(E26/SUM(E$24:E$27)) -> #REF! | Q26: =$N26*(F26/SUM(F$24:F$27)) -> #REF! | R26: =$N26*(G26/SUM(G$24:G$27)) -> #REF! | S26: =$N26*(H26/SUM(H$24:H$27)) -> #REF! | T26: =$N26*(I26/SUM(I$24:I$27)) -> #REF! | U26: =$N26*(J26/SUM(J$24:J$27)) -> #REF! | V26: =$N26*(K26/SUM(K$24:K$27)) -> #REF! | W26: =$N26*(L26/SUM(L$24:L$27)) -> #REF! | X26: =$N26*(M26/SUM(M$24:M$27)) -> #REF!
A27: =A26+1 -> 24 | B27: Fabricação de produtos farmoquímicos e farmacêuticos | C27: CH | D27: Chemical | E27: =VA!E27 -> 0 | F27: =VA!F27 -> 26947.356 | G27: =VA!G27 -> 26393.722 | H27: =VA!H27 -> 29958.78 | I27: =VA!I27 -> 33559.378 | J27: =VA!J27 -> 37418.05 | K27: =VA!K27 -> 41206.046 | L27: =VA!L27 -> 45479.975 | M27: =VA!M27 -> 50224.144 | N27: =#REF! -> #REF! | O27: share TJ intrasetorial | P27: =$N27*(E27/SUM(E$24:E$27)) -> #REF! | Q27: =$N27*(F27/SUM(F$24:F$27)) -> #REF! | R27: =$N27*(G27/SUM(G$24:G$27)) -> #REF! | S27: =$N27*(H27/SUM(H$24:H$27)) -> #REF! | T27: =$N27*(I27/SUM(I$24:I$27)) -> #REF! | U27: =$N27*(J27/SUM(J$24:J$27)) -> #REF! | V27: =$N27*(K27/SUM(K$24:K$27)) -> #REF! | W27: =$N27*(L27/SUM(L$24:L$27)) -> #REF! | X27: =$N27*(M27/SUM(M$24:M$27)) -> #REF!
A28: =A27+1 -> 25 | B28: Fabricação de produtos de borracha e de material plástico | C28: CH | D28: Chemical | E28: =VA!E28 -> 0 | F28: =VA!F28 -> 32764.333 | G28: =VA!G28 -> 30889.663 | H28: =VA!H28 -> 37217.363 | I28: =VA!I28 -> 42571.859 | J28: =VA!J28 -> 48089.451 | K28: =VA!K28 -> 53442.047 | L28: =VA!L28 -> 59396.675 | M28: =VA!M28 -> 65931.717 | N28: =#REF! -> #REF! | O28: share TJ intrasetorial | P28: =$N28 -> #REF! | Q28: =$N28 -> #REF! | R28: =$N28 -> #REF! | S28: =$N28 -> #REF! | T28: =$N28 -> #REF! | U28: =$N28 -> #REF! | V28: =$N28 -> #REF! | W28: =$N28 -> #REF! | X28: =$N28 -> #REF!
A29: =A28+1 -> 26 | B29: Fabricação de produtos de minerais não-metálicos (cimento e cerâmica) | C29: CE | D29: Cement and ceramics | E29: =VA!E29 -> 0 | F29: =VA!F29 -> 33078.788 | G29: =VA!G29 -> 29537.555 | H29: =VA!H29 -> 37685.562 | I29: =VA!I29 -> 43373.393 | J29: =VA!J29 -> 48864.824 | K29: =VA!K29 -> 54082.613 | L29: =VA!L29 -> 59703.86 | M29: =VA!M29 -> 65724.632 | N29: 1 | O29: MSG | P29: 1 | Q29: 1 | R29: 1 | S29: 1 | T29: 1 | U29: 1 | V29: 1 | W29: 1 | X29: 1
A30: =A29+1 -> 27 | B30: Produção de ferro-gusa/ferroligas, siderurgia e tubos de aço sem costura | C30: IS | D30: Iron and Steel | E30: =VA!E30 -> 0 | F30: =VA!F30 -> 26862.581 | G30: =VA!G30 -> 25620.253 | H30: =VA!H30 -> 30815.556 | I30: =VA!I30 -> 34919.617 | J30: =VA!J30 -> 39039.546 | K30: =VA!K30 -> 42948.587 | L30: =VA!L30 -> 47226.472 | M30: =VA!M30 -> 51848.121 | N30: 1 | O30: MSG | P30: 1 | Q30: 1 | R30: 1 | S30: 1 | T30: 1 | U30: 1 | V30: 1 | W30: 1 | X30: 1
A31: =A30+1 -> 28 | B31: Metalurgia de metais não-ferosos e a fundição de metais | C31: OI | D31: Metallurgy | E31: =VA!E31 -> 0 | F31: =VA!F31 -> 15806.688 | G31: =VA!G31 -> 15487.891 | H31: =VA!H31 -> 18212.572 | I31: =VA!I31 -> 20543.461 | J31: =VA!J31 -> 22956.106 | K31: =VA!K31 -> 25287.222 | L31: =VA!L31 -> 27872.055 | M31: =VA!M31 -> 30695.701 | N31: 1 | O31: MSG | P31: =$N31*1 -> 1 | Q31: =$N31*1 -> 1 | R31: =$N31*1 -> 1 | S31: =$N31*1 -> 1 | T31: =$N31*1 -> 1 | U31: =$N31*1 -> 1 | V31: =$N31*1 -> 1 | W31: =$N31*1 -> 1 | X31: =$N31*1 -> 1
A32: =A31+1 -> 29 | B32: Fabricação de produtos de metal, exceto máquinas e equipamentos | C32: OI | D32: Metallurgy | E32: =VA!E32 -> 0 | F32: =VA!F32 -> 40698.94 | G32: =VA!G32 -> 36166.006 | H32: =VA!H32 -> 43616.856 | I32: =VA!I32 -> 48984.45 | J32: =VA!J32 -> 54112.933 | K32: =VA!K32 -> 58733.505 | L32: =VA!L32 -> 63661.084 | M32: =VA!M32 -> 68844.421 | N32: =#REF! -> #REF! | O32: share TJ intrasetorial | P32: =$N32*E32/(E21+E32+E35) -> #REF! | Q32: =$N32*F32/(F21+F32+F35) -> #REF! | R32: =$N32*G32/(G21+G32+G35) -> #REF! | S32: =$N32*H32/(H21+H32+H35) -> #REF! | T32: =$N32*I32/(I21+I32+I35) -> #REF! | U32: =$N32*J32/(J21+J32+J35) -> #REF! | V32: =$N32*K32/(K21+K32+K35) -> #REF! | W32: =$N32*L32/(L21+L32+L35) -> #REF! | X32: =$N32*M32/(M21+M32+M35) -> #REF!
A33: =A32+1 -> 30 | B33: Fabricação de equipamentos de informática, produtos eletrônicos e ópticos | C33: OI | D33: Other industries | E33: =VA!E33 -> 0 | F33: =VA!F33 -> 19490.75 | G33: =VA!G33 -> 18240.095 | H33: =VA!H33 -> 22769.988 | I33: =VA!I33 -> 26694.119 | J33: =VA!J33 -> 30829.189 | K33: =VA!K33 -> 35018.804 | L33: =VA!L33 -> 39741.241 | M33: =VA!M33 -> 45016.491 | N33: =#REF! -> #REF! | O33: share TJ intrasetorial | P33: =$N33*1 -> #REF! | Q33: =$N33*1 -> #REF! | R33: =$N33*1 -> #REF! | S33: =$N33*1 -> #REF! | T33: =$N33*1 -> #REF! | U33: =$N33*1 -> #REF! | V33: =$N33*1 -> #REF! | W33: =$N33*1 -> #REF! | X33: =$N33*1 -> #REF!
A34: =A33+1 -> 31 | B34: Fabricação de máquinas e equipamentos elétricos | C34: OI | D34: Other industries | E34: =VA!E34 -> 0 | F34: =VA!F34 -> 21488.702 | G34: =VA!G34 -> 19659.048 | H34: =VA!H34 -> 24246.461 | I34: =VA!I34 -> 27999.387 | J34: =VA!J34 -> 31823.144 | K34: =VA!K34 -> 35518.154 | L34: =VA!L34 -> 39592.884 | M34: =VA!M34 -> 44029.516 | N34: =#REF! -> #REF! | O34: share TJ intrasetorial | P34: =$N34*E34/(E34+E37+E38) -> #REF! | Q34: =$N34*F34/(F34+F37+F38) -> #REF! | R34: =$N34*G34/(G34+G37+G38) -> #REF! | S34: =$N34*H34/(H34+H37+H38) -> #REF! | T34: =$N34*I34/(I34+I37+I38) -> #REF! | U34: =$N34*J34/(J34+J37+J38) -> #REF! | V34: =$N34*K34/(K34+K37+K38) -> #REF! | W34: =$N34*L34/(L34+L37+L38) -> #REF! | X34: =$N34*M34/(M34+M37+M38) -> #REF!
A35: =A34+1 -> 32 | B35: Fabricação de máquinas e equipamentos mecânicos | C35: OI | D35: Other industries | E35: =VA!E35 -> 0 | F35: =VA!F35 -> 46204.553 | G35: =VA!G35 -> 40544.547 | H35: =VA!H35 -> 53325.475 | I35: =VA!I35 -> 62802.419 | J35: =VA!J35 -> 72195.94 | K35: =VA!K35 -> 81257.089 | L35: =VA!L35 -> 91118.606 | M35: =VA!M35 -> 101751.63 | N35: =#REF! -> #REF! | O35: share TJ intrasetorial | P35: =$N35*E35/(E21+E32+E35) -> #REF! | Q35: =$N35*F35/(F21+F32+F35) -> #REF! | R35: =$N35*G35/(G21+G32+G35) -> #REF! | S35: =$N35*H35/(H21+H32+H35) -> #REF! | T35: =$N35*I35/(I21+I32+I35) -> #REF! | U35: =$N35*J35/(J21+J32+J35) -> #REF! | V35: =$N35*K35/(K21+K32+K35) -> #REF! | W35: =$N35*L35/(L21+L32+L35) -> #REF! | X35: =$N35*M35/(M21+M32+M35) -> #REF!
A36: =A35+1 -> 33 | B36: Fabricação de automóveis, caminhões e ônibus, exceto peças | C36: OI | D36: Other industries | E36: =VA!E36 -> 0 | F36: =VA!F36 -> 32449.587 | G36: =VA!G36 -> 31342.136 | H36: =VA!H36 -> 38812.961 | I36: =VA!I36 -> 45040.592 | J36: =VA!J36 -> 51460.461 | K36: =VA!K36 -> 57793.856 | L36: =VA!L36 -> 64809.815 | M36: =VA!M36 -> 72500.922 | N36: =#REF! -> #REF! | O36: share TJ intrasetorial | P36: =$N36*1 -> #REF! | Q36: =$N36*1 -> #REF! | R36: =$N36*1 -> #REF! | S36: =$N36*1 -> #REF! | T36: =$N36*1 -> #REF! | U36: =$N36*1 -> #REF! | V36: =$N36*1 -> #REF! | W36: =$N36*1 -> #REF! | X36: =$N36*1 -> #REF!
A37: =A36+1 -> 34 | B37: Fabricação de peças e acessórios para veículos automotores | C37: OI | D37: Other industries | E37: =VA!E37 -> 0 | F37: =VA!F37 -> 23038.197 | G37: =VA!G37 -> 21335.571 | H37: =VA!H37 -> 26239.089 | I37: =VA!I37 -> 30371.367 | J37: =VA!J37 -> 34594.856 | K37: =VA!K37 -> 38622.379 | L37: =VA!L37 -> 43069.847 | M37: =VA!M37 -> 47902.207 | N37: =#REF! -> #REF! | O37: share TJ intrasetorial | P37: =$N37*E37/(E34+E37+E38) -> #REF! | Q37: =$N37*F37/(F34+F37+F38) -> #REF! | R37: =$N37*G37/(G34+G37+G38) -> #REF! | S37: =$N37*H37/(H34+H37+H38) -> #REF! | T37: =$N37*I37/(I34+I37+I38) -> #REF! | U37: =$N37*J37/(J34+J37+J38) -> #REF! | V37: =$N37*K37/(K34+K37+K38) -> #REF! | W37: =$N37*L37/(L34+L37+L38) -> #REF! | X37: =$N37*M37/(M34+M37+M38) -> #REF!
A38: =A37+1 -> 35 | B38: Fabricação de outros equipamentos de transporte, exceto veículos automotores | C38: OI | D38: Other industries | E38: =VA!E38 -> 0 | F38: =VA!F38 -> 15235.909 | G38: =VA!G38 -> 15423.943 | H38: =VA!H38 -> 19020.918 | I38: =VA!I38 -> 22192.379 | J38: =VA!J38 -> 25530.085 | K38: =VA!K38 -> 28855.892 | L38: =VA!L38 -> 32597.283 | M38: =VA!M38 -> 36752.279 | N38: =#REF! -> #REF! | O38: share TJ intrasetorial | P38: =$N38*E38/(E34+E37+E38) -> #REF! | Q38: =$N38*F38/(F34+F37+F38) -> #REF! | R38: =$N38*G38/(G34+G37+G38) -> #REF! | S38: =$N38*H38/(H34+H37+H38) -> #REF! | T38: =$N38*I38/(I34+I37+I38) -> #REF! | U38: =$N38*J38/(J34+J37+J38) -> #REF! | V38: =$N38*K38/(K34+K37+K38) -> #REF! | W38: =$N38*L38/(L34+L37+L38) -> #REF! | X38: =$N38*M38/(M34+M37+M38) -> #REF!
A39: =A38+1 -> 36 | B39: Fabricação de móveis e de produtos de indústrias diversas | C39: OI | D39: Other industries | E39: =VA!E39 -> 0 | F39: =VA!F39 -> 36596.086 | G39: =VA!G39 -> 36043.502 | H39: =VA!H39 -> 42134.373 | I39: =VA!I39 -> 47988.84 | J39: =VA!J39 -> 54272.535 | K39: =VA!K39 -> 60593.373 | L39: =VA!L39 -> 67737.796 | M39: =VA!M39 -> 75708.547 | N39: =#REF! -> #REF! | O39: share TJ intrasetorial | P39: =$N39*E39/(SUM(E38:E39)) -> #REF! | Q39: =$N39*F39/(SUM(F39:F40)) -> #REF! | R39: =$N39*G39/(SUM(G39:G40)) -> #REF! | S39: =$N39*H39/(SUM(H39:H40)) -> #REF! | T39: =$N39*I39/(SUM(I39:I40)) -> #REF! | U39: =$N39*J39/(SUM(J39:J40)) -> #REF! | V39: =$N39*K39/(SUM(K39:K40)) -> #REF! | W39: =$N39*L39/(SUM(L39:L40)) -> #REF! | X39: =$N39*M39/(SUM(M39:M40)) -> #REF!
A40: =A39+1 -> 37 | B40: Manutenção, reparação e instalação de máquinas e equipamentos | C40: OI | D40: Other industries | E40: =VA!E40 -> 0 | F40: =VA!F40 -> 26822.386 | G40: =VA!G40 -> 23926.537 | H40: =VA!H40 -> 28361.702 | I40: =VA!I40 -> 31608.648 | J40: =VA!J40 -> 34728.305 | K40: =VA!K40 -> 37523.005 | L40: =VA!L40 -> 40520.631 | M40: =VA!M40 -> 43685.942 | N40: =#REF! -> #REF! | O40: share TJ intrasetorial | P40: =$N40*E40/(SUM(E39:E40)) -> #REF! | Q40: =$N40*F40/(SUM(F39:F40)) -> #REF! | R40: =$N40*G40/(SUM(G39:G40)) -> #REF! | S40: =$N40*H40/(SUM(H39:H40)) -> #REF! | T40: =$N40*I40/(SUM(I39:I40)) -> #REF! | U40: =$N40*J40/(SUM(J39:J40)) -> #REF! | V40: =$N40*K40/(SUM(K39:K40)) -> #REF! | W40: =$N40*L40/(SUM(L39:L40)) -> #REF! | X40: =$N40*M40/(SUM(M39:M40)) -> #REF!
A41: =A40+1 -> 38 | B41: Energia elétrica, gás natural e outras utilidades | C41: ELECT | D41: Electricity | E41: =VA!E41 -> 0 | F41: =VA!F41 -> 101155.39 | G41: =VA!G41 -> 100061.15 | H41: =VA!H41 -> 110848.75 | I41: =VA!I41 -> 121132.19 | J41: =VA!J41 -> 132088.87 | K41: =VA!K41 -> 142829.46 | L41: =VA!L41 -> 154936.44 | M41: =VA!M41 -> 168359.69 | N41: 1 | O41: MSG | P41: =$N41*1 -> 1 | Q41: =$N41*1 -> 1 | R41: =$N41*1 -> 1 | S41: =$N41*1 -> 1 | T41: =$N41*1 -> 1 | U41: =$N41*1 -> 1 | V41: =$N41*1 -> 1 | W41: =$N41*1 -> 1 | X41: =$N41*1 -> 1
...

Sheet ENERGIA FINAL_MSG
B1: No. Atividades | D1: Classes e atividades MESSAGE | F1: Petróleo e derivados + GN (incluindo coque) | O1: Eletricidade | X1: Carvão Mineral (nacional + importado) | AG1: Carvão Vegetal | AP1: Lenha (sem bagaço) | AY1: Bagaço de Cana | BH1: Etanol | BQ1: Outros (liquor negro, nuclear) | BZ1: Biodiesel | CI1: Biocombustíveis avançados | CR1: Biometano | DA1: Total | DK1: BEN_2010
F2: Refino de petróleo e coquerias | O2: Energia elétrica, gás natural e outras utilidades | X2: Extração de carvão mineral e de minerais não-metálicos | AC2: Importações | AG2: Não encontrado | AP2: Não encontrado | AY2: Fabricação e refino de açúcar | BC2: Fabricação de biocombustíveis | BH2: Fabricação de biocombustíveis | BQ2: Fabricação de celulose, papel e produtos de papel | BV2: Energia elétrica, gás natural e outras utilidades | BZ2: Fabricação de biocombustíveis | CI2: Fabricação de biocombustíveis | CR2: Fabricação de biocombustíveis
F3: 2010 | G3: 2015 | H3: 2020 | I3: 2025 | J3: 2030 | K3: 2035 | L3: 2040 | M3: 2045 | N3: 2050 | O3: 2010 | P3: 2015 | Q3: 2020 | R3: 2025 | S3: 2030 | T3: 2035 | U3: 2040 | V3: 2045 | W3: 2050 | X3: 2010 | Y3: 2015 | Z3: 2020 | AA3: 2025 | AB3: 2030 | AC3: 2035 | AD3: 2040 | AE3: 2045 | AF3: 2050 | AG3: 2010 | AH3: 2015 | AI3: 2020 | AJ3: 2025 | AK3: 2030 | AL3: 2035 | AM3: 2040 | AN3: 2045 | AO3: 2050 | AP3: 2010 | AQ3: 2015 | AR3: 2020 | AS3: 2025 | AT3: 2030 | AU3: 2035 | AV3: 2040 | AW3: 2045 | AX3: 2050 | AY3: 2010 | AZ3: 2015 | BA3: 2020 | BB3: 2025 | BC3: 2030 | BD3: 2035 | BE3: 2040 | BF3: 2045 | BG3: 2050 | BH3: 2010 | BI3: 2015 | BJ3: 2020 | BK3: 2025 | BL3: 2030 | BM3: 2035 | BN3: 2040 | BO3: 2045 | BP3: 2050 | BQ3: 2010 | BR3: 2015 | BS3: 2020 | BT3: 2025 | BU3: 2030 | BV3: 2035 | BW3: 2040 | BX3: 2045 | BY3: 2050 | BZ3: 2010 | CA3: 2015 | CB3: 2020 | CC3: 2025 | CD3: 2030 | CE3: 2035 | CF3: 2040 | CG3: 2045 | CH3: 2050 | CI3: 2010 | CJ3: 2015 | CK3: 2020 | CL3: 2025 | CM3: 2030 | CN3: 2035 | CO3: 2040 | CP3: 2045 | CQ3: 2050 | CR3: 2010 | CS3: 2015 | CT3: 2020 | CU3: 2025 | CV3: 2030 | CW3: 2035 | CX3: 2040 | CY3: 2045 | CZ3: 2050 | DA3: 2010 | DB3: 2015 | DC3: 2020 | DD3: 2025 | DE3: 2030 | DF3: 2035 | DG3: 2040 | DH3: 2045 | DI3: 2050 | DK3: 2010 | DL3: Diferença 2010
A4: Aux | F4: ( ktep ) | O4: ( ktep ) | X4: ( ktep ) | AG4: ( ktep ) | AP4: ( ktep ) | AY4: ( ktep ) | BH4: ( ktep ) | BQ4: ( ktep ) | BZ4: ( ktep ) | CI4: ( ktep ) | CR4: ( ktep ) | DA4: ( ktep ) | DK4: ktep | DL4: ktep
A5: 19 | B5: 1 | C5: Agricultura, silvicultura, exploração florestal | D5: AGR | E5: Agriculture | F5: 5561.9263 | G5: 5915.4851 | H5: 5965.0088 | I5: 6677.9708 | J5: 7338.577 | K5: 7808.389 | L5: 8137.4785 | M5: 8316.31 | N5: 6181.6349 | O5: 1622.5107 | P5: 2302.6637 | Q5: 2790.7048 | R5: 2926.1297 | S5: 2865.1903 | T5: 2830.3969 | U5: 2823.0745 | V5: 2748.6945 | W5: 2879.7531 | X5: 0 | Y5: 0 | Z5: 0 | AA5: 0 | AB5: 0 | AC5: 0 | AD5: 0 | AE5: 0 | AF5: 0 | AG5: 5.7053749 | AH5: 6.0631376 | AI5: 6.8163224 | AJ5: 6.8163224 | AK5: 6.8163224 | AL5: 6.8163224 | AM5: 6.8163224 | AN5: 6.8163224 | AO5: 6.8163224 | AP5: 1900.0646 | AQ5: 2125.6171 | AR5: 2421.5976 | AS5: 2374.5145 | AT5: 2576.8312 | AU5: 2548.7201 | AV5: 2795.2609 | AW5: 2907.2045 | AX5: 2770.6377 | AY5: 0 | AZ5: 0 | BA5: 0 | BB5: 0 | BC5: 0 | BD5: 0 | BE5: 0 | BF5: 0 | BG5: 0 | BH5: 5.9501599 | BI5: 9.6407654 | BJ5: 6.6280262 | BK5: 15.139014 | BL5: 17.473887 | BM5: 19.582805 | BN5: 21.465767 | BO5: 23.122773 | BP5: 24.553824 | BQ5: 0 | BR5: 0 | BS5: 0 | BT5: 0 | BU5: 0 | BV5: 0 | BW5: 0 | BX5: 0 | BY5: 0 | BZ5: 204.09717 | CA5: 223.03891 | CB5: 593.62483 | CC5: 897.13408 | CD5: 966.89707 | CE5: 1012.9461 | CF5: 1069.0832 | CG5: 1103.2366 | CH5: 581.42816 | CI5: 0.11590302 | CJ5: 0.018957218 | CK5: 0.036641086 | CL5: 0 | CM5: 0 | CN5: 79.145116 | CO5: 29.93871 | CP5: 68.083643 | CQ5: 3536.2181 | CR5: 0 | CS5: 0 | CT5: 0 | CU5: 0 | CV5: 0 | CW5: 0 | CX5: 0 | CY5: 0 | CZ5: 0 | DA5: 9300.3702 | DB5: 10582.528 | DC5: 11784.417 | DD5: 12897.704 | DE5: 13771.786 | DF5: 14305.996 | DG5: 14883.118 | DH5: 15173.468 | DI5: 15981.042 | DK5: 10027 | DL5: 726.62979
A6: 27 | B6: 2 | C6: Pecuária, inclusive o apoio à pecuária | D6: AGR | E6: Agriculture | F6: 5561.9263 | G6: 5915.4851 | H6: 5965.0088 | I6: 6677.9708 | J6: 7338.577 | K6: 7808.389 | L6: 8137.4785 | M6: 8316.31 | N6: 6181.6349 | O6: 1622.5107 | P6: 2302.6637 | Q6: 2790.7048 | R6: 2926.1297 | S6: 2865.1903 | T6: 2830.3969 | U6: 2823.0745 | V6: 2748.6945 | W6: 2879.7531 | X6: 0 | Y6: 0 | Z6: 0 | AA6: 0 | AB6: 0 | AC6: 0 | AD6: 0 | AE6: 0 | AF6: 0 | AG6: 5.7053749 | AH6: 6.0631376 | AI6: 6.8163224 | AJ6: 6.8163224 | AK6: 6.8163224 | AL6: 6.8163224 | AM6: 6.8163224 | AN6: 6.8163224 | AO6: 6.8163224 | AP6: 1900.0646 | AQ6: 2125.6171 | AR6: 2421.5976 | AS6: 2374.5145 | AT6: 2576.8312 | AU6: 2548.7201 | AV6: 2795.2609 | AW6: 2907.2045 | AX6: 2770.6377 | AY6: 0 | AZ6: 0 | BA6: 0 | BB6: 0 | BC6: 0 | BD6: 0 | BE6: 0 | BF6: 0 | BG6: 0 | BH6: 5.9501599 | BI6: 9.6407654 | BJ6: 6.6280262 | BK6: 15.139014 | BL6: 17.473887 | BM6: 19.582805 | BN6: 21.465767 | BO6: 23.122773 | BP6: 24.553824 | BQ6: 0 | BR6: 0 | BS6: 0 | BT6: 0 | BU6: 0 | BV6: 0 | BW6: 0 | BX6: 0 | BY6: 0 | BZ6: 204.09717 | CA6: 223.03891 | CB6: 593.62483 | CC6: 897.13408 | CD6: 966.89707 | CE6: 1012.9461 | CF6: 1069.0832 | CG6: 1103.2366 | CH6: 581.42816 | CI6: 0.11590302 | CJ6: 0.018957218 | CK6: 0.036641086 | CL6: 0 | CM6: 0 | CN6: 79.145116 | CO6: 29.93871 | CP6: 68.083643 | CQ6: 3536.2181 | CR6: 0 | CS6: 0 | CT6: 0 | CU6: 0 | CV6: 0 | CW6: 0 | CX6: 0 | CY6: 0 | CZ6: 0 | DA6: 9300.3702 | DB6: 10582.528 | DC6: 11784.417 | DD6: 12897.704 | DE6: 13771.786 | DF6: 14305.996 | DG6: 14883.118 | DH6: 15173.468 | DI6: 15981.042
B7: 3 | C7: Produção florestal; pesca e aquicultura | D7: AGR | E7: Agriculture | F7: 5561.9263 | G7: 5915.4851 | H7: 5965.0088 | I7: 6677.9708 | J7: 7338.577 | K7: 7808.389 | L7: 8137.4785 | M7: 8316.31 | N7: 6181.6349 | O7: 1622.5107 | P7: 2302.6637 | Q7: 2790.7048 | R7: 2926.1297 | S7: 2865.1903 | T7: 2830.3969 | U7: 2823.0745 | V7: 2748.6945 | W7: 2879.7531 | X7: 0 | Y7: 0 | Z7: 0 | AA7: 0 | AB7: 0 | AC7: 0 | AD7: 0 | AE7: 0 | AF7: 0 | AG7: 5.7053749 | AH7: 6.0631376 | AI7: 6.8163224 | AJ7: 6.8163224 | AK7: 6.8163224 | AL7: 6.8163224 | AM7: 6.8163224 | AN7: 6.8163224 | AO7: 6.8163224 | AP7: 1900.0646 | AQ7: 2125.6171 | AR7: 2421.5976 | AS7: 2374.5145 | AT7: 2576.8312 | AU7: 2548.7201 | AV7: 2795.2609 | AW7: 2907.2045 | AX7: 2770.6377 | AY7: 0 | AZ7: 0 | BA7: 0 | BB7: 0 | BC7: 0 | BD7: 0 | BE7: 0 | BF7: 0 | BG7: 0 | BH7: 5.9501599 | BI7: 9.6407654 | BJ7: 6.6280262 | BK7: 15.139014 | BL7: 17.473887 | BM7: 19.582805 | BN7: 21.465767 | BO7: 23.122773 | BP7: 24.553824 | BQ7: 0 | BR7: 0 | BS7: 0 | BT7: 0 | BU7: 0 | BV7: 0 | BW7: 0 | BX7: 0 | BY7: 0 | BZ7: 204.09717 | CA7: 223.03891 | CB7: 593.62483 | CC7: 897.13408 | CD7: 966.89707 | CE7: 1012.9461 | CF7: 1069.0832 | CG7: 1103.2366 | CH7: 581.42816 | CI7: 0.11590302 | CJ7: 0.018957218 | CK7: 0.036641086 | CL7: 0 | CM7: 0 | CN7: 79.145116 | CO7: 29.93871 | CP7: 68.083643 | CQ7: 3536.2181 | CR7: 0 | CS7: 0 | CT7: 0 | CU7: 0 | CV7: 0 | CW7: 0 | CX7: 0 | CY7: 0 | CZ7: 0 | DA7: 9300.3702 | DB7: 10582.528 | DC7: 11784.417 | DD7: 12897.704 | DE7: 13771.786 | DF7: 14305.996 | DG7: 14883.118 | DH7: 15173.468 | DI7: 15981.042
B8: 4 | C8: Extração de carvão mineral e de minerais não-metálicos | D8: OI | E8: Mining | F8: 2195.6254 | G8: 2230.3505 | H8: 1088.9483 | I8: 1234.1451 | J8: 1411.1286 | K8: 1661.4078 | L8: 1495.3999 | M8: 1342.8518 | N8: 769.67346 | O8: 971.60764 | P8: 1095.3363 | Q8: 1016.4666 | R8: 1170.294 | S8: 1394.008 | T8: 1595.6679 | U8: 1919.319 | V8: 2234.096 | W8: 2514.9044 | X8: 0 | Y8: 0 | Z8: 0 | AA8: 0 | AB8: 0 | AC8: 0 | AD8: 0 | AE8: 0 | AF8: 0 | AG8: 0 | AH8: 0 | AI8: 0 | AJ8: 0 | AK8: 0 | AL8: 0 | AM8: 0 | AN8: 0 | AO8: 0 | AP8: 0 | AQ8: 0 | AR8: 0 | AS8: 0 | AT8: 0 | AU8: 0 | AV8: 0 | AW8: 0 | AX8: 0 | AY8: 0 | AZ8: 0 | BA8: 0 | BB8: 0 | BC8: 0 | BD8: 0 | BE8: 0 | BF8: 0 | BG8: 0 | BH8: 0 | BI8: 0 | BJ8: 0 | BK8: 0 | BL8: 0 | BM8: 0 | BN8: 0 | BO8: 0 | BP8: 0 | BQ8: 0 | BR8: 0 | BS8: 0 | BT8: 0 | BU8: 0 | BV8: 0 | BW8: 0 | BX8: 0 | BY8: 0 | BZ8: 12.271857 | CA8: 18.464589 | CB8: 42.793334 | CC8: 69.762109 | CD8: 77.904278 | CE8: 93.944549 | CF8: 113.90171 | CG8: 132.24963 | CH8: 76.201351 | CI8: 2.5699277 | CJ8: 2.2159572 | CK8: 2.3515061 | CL8: 1.3898951 | CM8: 1.7014908 | CN8: 9.4234746 | CO8: 3.4228002 | CP8: 6.8447106 | CQ8: 460.71253 | CR8: 0 | CS8: 0 | CT8: 0 | CU8: 0.56385041 | CV8: 36.049749 | CW8: 110.25267 | CX8: 739.11749 | CY8: 1386.6062 | CZ8: 2143.0171 | DA8: 3182.0748 | DB8: 3346.3674 | DC8: 2150.5597 | DD8: 2476.155 | DE8: 2920.7921 | DF8: 3470.6965 | DG8: 4271.1609 | DH8: 5102.6483 | DI8: 5964.5088
B9: 5 | C9: Extração de petróleo e gás, inclusive as atividades de apoio | D9: OIL | E9: Oil and Gas | F9: 2794.8175 | G9: 3466 | H9: 2897.8231 | I9: 2320.727 | J9: 2741.5345 | K9: 2053.8744 | L9: 1417.3847 | M9: 799.33572 | N9: 768.03821 | O9: 0 | P9: 0 | Q9: 0 | R9: 0 | S9: 0 | T9: 0 | U9: 0 | V9: 0 | W9: 0 | X9: 0 | Y9: 0 | Z9: 0 | AA9: 0 | AB9: 0 | AC9: 0 | AD9: 0 | AE9: 0 | AF9: 0 | AG9: 0 | AH9: 0 | AI9: 0 | AJ9: 0 | AK9: 0 | AL9: 0 | AM9: 0 | AN9: 0 | AO9: 0 | AP9: 0 | AQ9: 0 | AR9: 0 | AS9: 0 | AT9: 0 | AU9: 0 | AV9: 0 | AW9: 0 | AX9: 0 | AY9: 0 | AZ9: 0 | BA9: 0 | BB9: 0 | BC9: 0 | BD9: 0 | BE9: 0 | BF9: 0 | BG9: 0 | BH9: 0 | BI9: 0 | BJ9: 0 | BK9: 0 | BL9: 0 | BM9: 0 | BN9: 0 | BO9: 0 | BP9: 0 | BQ9: 0 | BR9: 0 | BS9: 0 | BT9: 0 | BU9: 0 | BV9: 0 | BW9: 0 | BX9: 0 | BY9: 0 | BZ9: 0 | CA9: 0 | CB9: 0 | CC9: 0 | CD9: 0 | CE9: 0 | CF9: 0 | CG9: 0 | CH9: 0 | CI9: 0 | CJ9: 0 | CK9: 0 | CL9: 0 | CM9: 0 | CN9: 0 | CO9: 0 | CP9: 0 | CQ9: 0 | CR9: 0 | CS9: 0 | CT9: 0 | CU9: 0 | CV9: 0 | CW9: 0 | CX9: 0 | CY9: 0 | CZ9: 0 | DA9: 2794.8175 | DB9: 3466 | DC9: 2897.8231 | DD9: 2320.727 | DE9: 2741.5345 | DF9: 2053.8744 | DG9: 1417.3847 | DH9: 799.33572 | DI9: 768.03821
A10: 131 | B10: 6 | C10: Extração de minério de ferro, inclusive beneficiamentos e a aglomeração | D10: OI | E10: Mining | F10: 2195.6254 | G10: 2230.3505 | H10: 1088.9483 | I10: 1234.1451 | J10: 1411.1286 | K10: 1661.4078 | L10: 1495.3999 | M10: 1342.8518 | N10: 769.67346 | O10: 971.60764 | P10: 1095.3363 | Q10: 1016.4666 | R10: 1170.294 | S10: 1394.008 | T10: 1595.6679 | U10: 1919.319 | V10: 2234.096 | W10: 2514.9044 | X10: 0 | Y10: 0 | Z10: 0 | AA10: 0 | AB10: 0 | AC10: 0 | AD10: 0 | AE10: 0 | AF10: 0 | AG10: 0 | AH10: 0 | AI10: 0 | AJ10: 0 | AK10: 0 | AL10: 0 | AM10: 0 | AN10: 0 | AO10: 0 | AP10: 0 | AQ10: 0 | AR10: 0 | AS10: 0 | AT10: 0 | AU10: 0 | AV10: 0 | AW10: 0 | AX10: 0 | AY10: 0 | AZ10: 0 | BA10: 0 | BB10: 0 | BC10: 0 | BD10: 0 | BE10: 0 | BF10: 0 | BG10: 0 | BH10: 0 | BI10: 0 | BJ10: 0 | BK10: 0 | BL10: 0 | BM10: 0 | BN10: 0 | BO10: 0 | BP10: 0 | BQ10: 0 | BR10: 0 | BS10: 0 | BT10: 0 | BU10: 0 | BV10: 0 | BW10: 0 | BX10: 0 | BY10: 0 | BZ10: 12.271857 | CA10: 18.464589 | CB10: 42.793334 | CC10: 69.762109 | CD10: 77.904278 | CE10: 93.944549 | CF10: 113.90171 | CG10: 132.24963 | CH10: 76.201351 | CI10: 2.5699277 | CJ10: 2.2159572 | CK10: 2.3515061 | CL10: 1.3898951 | CM10: 1.7014908 | CN10: 9.4234746 | CO10: 3.4228002 | CP10: 6.8447106 | CQ10: 460.71253 | CR10: 0 | CS10: 0 | CT10: 0 | CU10: 0.56385041 | CV10: 36.049749 | CW10: 110.25267 | CX10: 739.11749 | CY10: 1386.6062 | CZ10: 2143.0171 | DA10: 3182.0748 | DB10: 3346.3674 | DC10: 2150.5597 | DD10: 2476.155 | DE10: 2920.7921 | DF10: 3470.6965 | DG10: 4271.1609 | DH10: 5102.6483 | DI10: 5964.5088 | DK10: 3182 | DL10: -0.074801163
A11: 139 | B11: 7 | C11: Extração de minerais metálicos não-ferrosos, inclusive beneficiamentos | D11: OI | E11: Mining | F11: 2195.6254 | G11: 2230.3505 | H11: 1088.9483 | I11: 1234.1451 | J11: 1411.1286 | K11: 1661.4078 | L11: 1495.3999 | M11: 1342.8518 | N11: 769.67346 | O11: 971.60764 | P11: 1095.3363 | Q11: 1016.4666 | R11: 1170.294 | S11: 1394.008 | T11: 1595.6679 | U11: 1919.319 | V11: 2234.096 | W11: 2514.9044 | X11: 0 | Y11: 0 | Z11: 0 | AA11: 0 | AB11: 0 | AC11: 0 | AD11: 0 | AE11: 0 | AF11: 0 | AG11: 0 | AH11: 0 | AI11: 0 | AJ11: 0 | AK11: 0 | AL11: 0 | AM11: 0 | AN11: 0 | AO11: 0 | AP11: 0 | AQ11: 0 | AR11: 0 | AS11: 0 | AT11: 0 | AU11: 0 | AV11: 0 | AW11: 0 | AX11: 0 | AY11: 0 | AZ11: 0 | BA11: 0 | BB11: 0 | BC11: 0 | BD11: 0 | BE11: 0 | BF11: 0 | BG11: 0 | BH11: 0 | BI11: 0 | BJ11: 0 | BK11: 0 | BL11: 0 | BM11: 0 | BN11: 0 | BO11: 0 | BP11: 0 | BQ11: 0 | BR11: 0 | BS11: 0 | BT11: 0 | BU11: 0 | BV11: 0 | BW11: 0 | BX11: 0 | BY11: 0 | BZ11: 12.271857 | CA11: 18.464589 | CB11: 42.793334 | CC11: 69.762109 | CD11: 77.904278 | CE11: 93.944549 | CF11: 113.90171 | CG11: 132.24963 | CH11: 76.201351 | CI11: 2.5699277 | CJ11: 2.2159572 | CK11: 2.3515061 | CL11: 1.3898951 | CM11: 1.7014908 | CN11: 9.4234746 | CO11: 3.4228002 | CP11: 6.8447106 | CQ11: 460.71253 | CR11: 0 | CS11: 0 | CT11: 0 | CU11: 0.56385041 | CV11: 36.049749 | CW11: 110.25267 | CX11: 739.11749 | CY11: 1386.6062 | CZ11: 2143.0171 | DA11: 3182.0748 | DB11: 3346.3674 | DC11: 2150.5597 | DD11: 2476.155 | DE11: 2920.7921 | DF11: 3470.6965 | DG11: 4271.1609 | DH11: 5102.6483 | DI11: 5964.5088
A12: 89 | B12: 8 | C12: Abate e produtos de carne, inclusive os produtos do laticínio e da pesca | D12: FB | E12: Food and Beverage | F12: 1339.2125 | G12: 1502.2778 | H12: 1458.8155 | I12: 1167.4862 | J12: 930.49001 | K12: 773.87569 | L12: 728.64735 | M12: 404.64914 | N12: 181.14409 | O12: 2319.3784 | P12: 2234.633 | Q12: 2515.7065 | R12: 2437.1742 | S12: 2288.2161 | T12: 2211.2173 | U12: 2136.6693 | V12: 2054.2279 | W12: 2031.7936 | X12: 0 | Y12: 0 | Z12: 0 | AA12: 0 | AB12: 0 | AC12: 0 | AD12: 0 | AE12: 0 | AF12: 0 | AG12: 0 | AH12: 0 | AI12: 0 | AJ12: 0 | AK12: 0 | AL12: 0 | AM12: 0 | AN12: 0 | AO12: 0 | AP12: 2263.6201 | AQ12: 2163.1626 | AR12: 2361.0295 | AS12: 3047.519 | AT12: 3693.2951 | AU12: 4079.2692 | AV12: 4169.9963 | AW12: 4381.761 | AX12: 4449.3451 | AY12: 5360.0628 | AZ12: 6941.2605 | BA12: 7148.9444 | BB12: 7307.016 | BC12: 7490.3805 | BD12: 8321.7468 | BE12: 9301.4757 | BF12: 9289.2527 | BG12: 9002.5479 | BH12: 0 | BI12: 0 | BJ12: 0 | BK12: 0 | BL12: 0 | BM12: 0 | BN12: 0 | BO12: 0 | BP12: 0 | BQ12: 0 | BR12: 0 | BS12: 0 | BT12: 0 | BU12: 0 | BV12: 0 | BW12: 0 | BX12: 0 | BY12: 0 | BZ12: 0 | CA12: 0 | CB12: 0 | CC12: 0 | CD12: 0 | CE12: 0 | CF12: 0 | CG12: 0 | CH12: 0 | CI12: 0.93283751 | CJ12: 0.66801116 | CK12: 1.419597 | CL12: 0.59477268 | CM12: 0.63041962 | CN12: 0.62705086 | CO12: 0.46207771 | CP12: 0.00065801071 | CQ12: 0.0067889121 | CR12: 0 | CS12: 0 | CT12: 0 | CU12: 1.8675326 | CV12: 81.194579 | CW12: 200.73747 | CX12: 499.16876 | CY12: 938.10539 | CZ12: 1335.9115 | DA12: 11283.207 | DB12: 12842.002 | DC12: 13485.915 | DD12: 13961.658 | DE12: 14484.207 | DF12: 15587.473 | DG12: 16836.419 | DH12: 17067.997 | DI12: 17000.749 | DK12: 23244 | DL12: 11960.793 | DM12: 4400 | DN12: temos mais bagaço e lenha
A13: 97 | B13: 9 | C13: Fabricação e refino de açúcar | D13: FB | E13: Food and Beverage | F13: 1339.2125 | G13: 1502.2778 | H13: 1458.8155 | I13: 1167.4862 | J13: 930.49001 | K13: 773.87569 | L13: 728.64735 | M13: 404.64914 | N13: 181.14409 | O13: 2319.3784 | P13: 2234.633 | Q13: 2515.7065 | R13: 2437.1742 | S13: 2288.2161 | T13: 2211.2173 | U13: 2136.6693 | V13: 2054.2279 | W13: 2031.7936 | X13: 0 | Y13: 0 | Z13: 0 | AA13: 0 | AB13: 0 | AC13: 0 | AD13: 0 | AE13: 0 | AF13: 0 | AG13: 0 | AH13: 0 | AI13: 0 | AJ13: 0 | AK13: 0 | AL13: 0 | AM13: 0 | AN13: 0 | AO13: 0 | AP13: 2263.6201 | AQ13: 2163.1626 | AR13: 2361.0295 | AS13: 3047.519 | AT13: 3693.2951 | AU13: 4079.2692 | AV13: 4169.9963 | AW13: 4381.761 | AX13: 4449.3451 | AY13: 5360.0628 | AZ13: 6941.2605 | BA13: 7148.9444 | BB13: 7307.016 | BC13: 7490.3805 | BD13: 8321.7468 | BE13: 9301.4757 | BF13: 9289.2527 | BG13: 9002.5479 | BH13: 0 | BI13: 0 | BJ13: 0 | BK13: 0 | BL13: 0 | BM13: 0 | BN13: 0 | BO13: 0 | BP13: 0 | BQ13: 0 | BR13: 0 | BS13: 0 | BT13: 0 | BU13: 0 | BV13: 0 | BW13: 0 | BX13: 0 | BY13: 0 | BZ13: 0 | CA13: 0 | CB13: 0 | CC13: 0 | CD13: 0 | CE13: 0 | CF13: 0 | CG13: 0 | CH13: 0 | CI13: 0.93283751 | CJ13: 0.66801116 | CK13: 1.419597 | CL13: 0.59477268 | CM13: 0.63041962 | CN13: 0.62705086 | CO13: 0.46207771 | CP13: 0.00065801071 | CQ13: 0.0067889121 | CR13: 0 | CS13: 0 | CT13: 0 | CU13: 1.8675326 | CV13: 81.194579 | CW13: 200.73747 | CX13: 499.16876 | CY13: 938.10539 | CZ13: 1335.9115 | DA13: 11283.207 | DB13: 12842.002 | DC13: 13485.915 | DD13: 13961.658 | DE13: 14484.207 | DF13: 15587.473 | DG13: 16836.419 | DH13: 17067.997 | DI13: 17000.749
B14: 10 | C14: Outros produtos alimentares | D14: FB | E14: Food and Beverage | F14: 1339.2125 | G14: 1502.2778 | H14: 1458.8155 | I14: 1167.4862 | J14: 930.49001 | K14: 773.87569 | L14: 728.64735 | M14: 404.64914 | N14: 181.14409 | O14: 2319.3784 | P14: 2234.633 | Q14: 2515.7065 | R14: 2437.1742 | S14: 2288.2161 | T14: 2211.2173 | U14: 2136.6693 | V14: 2054.2279 | W14: 2031.7936 | X14: 0 | Y14: 0 | Z14: 0 | AA14: 0 | AB14: 0 | AC14: 0 | AD14: 0 | AE14: 0 | AF14: 0 | AG14: 0 | AH14: 0 | AI14: 0 | AJ14: 0 | AK14: 0 | AL14: 0 | AM14: 0 | AN14: 0 | AO14: 0 | AP14: 2263.6201 | AQ14: 2163.1626 | AR14: 2361.0295 | AS14: 3047.519 | AT14: 3693.2951 | AU14: 4079.2692 | AV14: 4169.9963 | AW14: 4381.761 | AX14: 4449.3451 | AY14: 5360.0628 | AZ14: 6941.2605 | BA14: 7148.9444 | BB14: 7307.016 | BC14: 7490.3805 | BD14: 8321.7468 | BE14: 9301.4757 | BF14: 9289.2527 | BG14: 9002.5479 | BH14: 0 | BI14: 0 | BJ14: 0 | BK14: 0 | BL14: 0 | BM14: 0 | BN14: 0 | BO14: 0 | BP14: 0 | BQ14: 0 | BR14: 0 | BS14: 0 | BT14: 0 | BU14: 0 | BV14: 0 | BW14: 0 | BX14: 0 | BY14: 0 | BZ14: 0 | CA14: 0 | CB14: 0 | CC14: 0 | CD14: 0 | CE14: 0 | CF14: 0 | CG14: 0 | CH14: 0 | CI14: 0.93283751 | CJ14: 0.66801116 | CK14: 1.419597 | CL14: 0.59477268 | CM14: 0.63041962 | CN14: 0.62705086 | CO14: 0.46207771 | CP14: 0.00065801071 | CQ14: 0.0067889121 | CR14: 0 | CS14: 0 | CT14: 0 | CU14: 1.8675326 | CV14: 81.194579 | CW14: 200.73747 | CX14: 499.16876 | CY14: 938.10539 | CZ14: 1335.9115 | DA14: 11283.207 | DB14: 12842.002 | DC14: 13485.915 | DD14: 13961.658 | DE14: 14484.207 | DF14: 15587.473 | DG14: 16836.419 | DH14: 17067.997 | DI14: 17000.749
B15: 11 | C15: Fabricação de bebidas | D15: FB | E15: Food and Beverage | F15: 1339.2125 | G15: 1502.2778 | H15: 1458.8155 | I15: 1167.4862 | J15: 930.49001 | K15: 773.87569 | L15: 728.64735 | M15: 404.64914 | N15: 181.14409 | O15: 2319.3784 | P15: 2234.633 | Q15: 2515.7065 | R15: 2437.1742 | S15: 2288.2161 | T15: 2211.2173 | U15: 2136.6693 | V15: 2054.2279 | W15: 2031.7936 | X15: 0 | Y15: 0 | Z15: 0 | AA15: 0 | AB15: 0 | AC15: 0 | AD15: 0 | AE15: 0 | AF15: 0 | AG15: 0 | AH15: 0 | AI15: 0 | AJ15: 0 | AK15: 0 | AL15: 0 | AM15: 0 | AN15: 0 | AO15: 0 | AP15: 2263.6201 | AQ15: 2163.1626 | AR15: 2361.0295 | AS15: 3047.519 | AT15: 3693.2951 | AU15: 4079.2692 | AV15: 4169.9963 | AW15: 4381.761 | AX15: 4449.3451 | AY15: 5360.0628 | AZ15: 6941.2605 | BA15: 7148.9444 | BB15: 7307.016 | BC15: 7490.3805 | BD15: 8321.7468 | BE15: 9301.4757 | BF15: 9289.2527 | BG15: 9002.5479 | BH15: 0 | BI15: 0 | BJ15: 0 | BK15: 0 | BL15: 0 | BM15: 0 | BN15: 0 | BO15: 0 | BP15: 0 | BQ15: 0 | BR15: 0 | BS15: 0 | BT15: 0 | BU15: 0 | BV15: 0 | BW15: 0 | BX15: 0 | BY15: 0 | BZ15: 0 | CA15: 0 | CB15: 0 | CC15: 0 | CD15: 0 | CE15: 0 | CF15: 0 | CG15: 0 | CH15: 0 | CI15: 0.93283751 | CJ15: 0.66801116 | CK15: 1.419597 | CL15: 0.59477268 | CM15: 0.63041962 | CN15: 0.62705086 | CO15: 0.46207771 | CP15: 0.00065801071 | CQ15: 0.0067889121 | CR15: 0 | CS15: 0 | CT15: 0 | CU15: 1.8675326 | CV15: 81.194579 | CW15: 200.73747 | CX15: 499.16876 | CY15: 938.10539 | CZ15: 1335.9115 | DA15: 11283.207 | DB15: 12842.002 | DC15: 13485.915 | DD15: 13961.658 | DE15: 14484.207 | DF15: 15587.473 | DG15: 16836.419 | DH15: 17067.997 | DI15: 17000.749
B16: 12 | C16: Fabricação de produtos do fumo | D16: FB | E16: Food and Beverage | F16: 1339.2125 | G16: 1502.2778 | H16: 1458.8155 | I16: 1167.4862 | J16: 930.49001 | K16: 773.87569 | L16: 728.64735 | M16: 404.64914 | N16: 181.14409 | O16: 2319.3784 | P16: 2234.633 | Q16: 2515.7065 | R16: 2437.1742 | S16: 2288.2161 | T16: 2211.2173 | U16: 2136.6693 | V16: 2054.2279 | W16: 2031.7936 | X16: 0 | Y16: 0 | Z16: 0 | AA16: 0 | AB16: 0 | AC16: 0 | AD16: 0 | AE16: 0 | AF16: 0 | AG16: 0 | AH16: 0 | AI16: 0 | AJ16: 0 | AK16: 0 | AL16: 0 | AM16: 0 | AN16: 0 | AO16: 0 | AP16: 2263.6201 | AQ16: 2163.1626 | AR16: 2361.0295 | AS16: 3047.519 | AT16: 3693.2951 | AU16: 4079.2692 | AV16: 4169.9963 | AW16: 4381.761 | AX16: 4449.3451 | AY16: 5360.0628 | AZ16: 6941.2605 | BA16: 7148.9444 | BB16: 7307.016 | BC16: 7490.3805 | BD16: 8321.7468 | BE16: 9301.4757 | BF16: 9289.2527 | BG16: 9002.5479 | BH16: 0 | BI16: 0 | BJ16: 0 | BK16: 0 | BL16: 0 | BM16: 0 | BN16: 0 | BO16: 0 | BP16: 0 | BQ16: 0 | BR16: 0 | BS16: 0 | BT16: 0 | BU16: 0 | BV16: 0 | BW16: 0 | BX16: 0 | BY16: 0 | BZ16: 0 | CA16: 0 | CB16: 0 | CC16: 0 | CD16: 0 | CE16: 0 | CF16: 0 | CG16: 0 | CH16: 0 | CI16: 0.93283751 | CJ16: 0.66801116 | CK16: 1.419597 | CL16: 0.59477268 | CM16: 0.63041962 | CN16: 0.62705086 | CO16: 0.46207771 | CP16: 0.00065801071 | CQ16: 0.0067889121 | CR16: 0 | CS16: 0 | CT16: 0 | CU16: 1.8675326 | CV16: 81.194579 | CW16: 200.73747 | CX16: 499.16876 | CY16: 938.10539 | CZ16: 1335.9115 | DA16: 11283.207 | DB16: 12842.002 | DC16: 13485.915 | DD16: 13961.658 | DE16: 14484.207 | DF16: 15587.473 | DG16: 16836.419 | DH16: 17067.997 | DI16: 17000.749
A17: 159 | B17: 13 | C17: Fabricação de produtos têxteis | D17: TX | E17: Textile | F17: 390.71649 | G17: 271.62222 | H17: 210.85669 | I17: 229.41646 | J17: 197.0341 | K17: 168.23064 | L17: 131.92313 | M17: 74.465417 | N17: 30.314912 | O17: 714.40218 | P17: 559.40504 | Q17: 483.19705 | R17: 532.51461 | S17: 563.29305 | T17: 564.45477 | U17: 560.34923 | V17: 547.92522 | W17: 539.95946 | X17: 0 | Y17: 0 | Z17: 0 | AA17: 0 | AB17: 0 | AC17: 0 | AD17: 0 | AE17: 0 | AF17: 0 | AG17: 0 | AH17: 0 | AI17: 0 | AJ17: 0 | AK17: 0 | AL17: 0 | AM17: 0 | AN17: 0 | AO17: 0 | AP17: 91.824977 | AQ17: 61.644207 | AR17: 52.892335 | AS17: 92.233806 | AT17: 106.04586 | AU17: 115.67924 | AV17: 115.09093 | AW17: 114.98564 | AX17: 112.85977 | AY17: 0 | AZ17: 0 | BA17: 0 | BB17: 0 | BC17: 0 | BD17: 0 | BE17: 0 | BF17: 0 | BG17: 0 | BH17: 0 | BI17: 0 | BJ17: 0 | BK17: 0 | BL17: 0 | BM17: 0 | BN17: 0 | BO17: 0 | BP17: 0 | BQ17: 0 | BR17: 0 | BS17: 0 | BT17: 0 | BU17: 0 | BV17: 0 | BW17: 0 | BX17: 0 | BY17: 0 | BZ17: 0 | CA17: 0 | CB17: 0 | CC17: 0 | CD17: 0 | CE17: 0 | CF17: 0 | CG17: 0 | CH17: 0 | CI17: 0.13201595 | CJ17: 0.040293127 | CK17: 0.026721222 | CL17: 0.080538579 | CM17: 0.015936744 | CN17: 0.015481301 | CO17: 8.3497153e-07 | CP17: 2.7357811 | CQ17: 2.8497186 | CR17: 0 | CS17: 0 | CT17: 0 | CU17: 0.3102237 | CV17: 20.540912 | CW17: 55.794524 | CX17: 102.49936 | CY17: 172.28205 | CZ17: 223.59658 | DA17: 1197.0757 | DB17: 892.71176 | DC17: 746.97279 | DD17: 854.55564 | DE17: 886.92986 | DF17: 904.17465 | DG17: 909.86265 | DH17: 912.3941 | DI17: 909.58044 | DK17: 1212 | DL17: 14.92433
A18: 167 | B18: 14 | C18: Confecção de artefatos do vestuário e acessórios | D18: TX | E18: Textile | F18: 390.71649 | G18: 271.62222 | H18: 210.85669 | I18: 229.41646 | J18: 197.0341 | K18: 168.23064 | L18: 131.92313 | M18: 74.465417 | N18: 30.314912 | O18: 714.40218 | P18: 559.40504 | Q18: 483.19705 | R18: 532.51461 | S18: 563.29305 | T18: 564.45477 | U18: 560.34923 | V18: 547.92522 | W18: 539.95946 | X18: 0 | Y18: 0 | Z18: 0 | AA18: 0 | AB18: 0 | AC18: 0 | AD18: 0 | AE18: 0 | AF18: 0 | AG18: 0 | AH18: 0 | AI18: 0 | AJ18: 0 | AK18: 0 | AL18: 0 | AM18: 0 | AN18: 0 | AO18: 0 | AP18: 91.824977 | AQ18: 61.644207 | AR18: 52.892335 | AS18: 92.233806 | AT18: 106.04586 | AU18: 115.67924 | AV18: 115.09093 | AW18: 114.98564 | AX18: 112.85977 | AY18: 0 | AZ18: 0 | BA18: 0 | BB18: 0 | BC18: 0 | BD18: 0 | BE18: 0 | BF18: 0 | BG18: 0 | BH18: 0 | BI18: 0 | BJ18: 0 | BK18: 0 | BL18: 0 | BM18: 0 | BN18: 0 | BO18: 0 | BP18: 0 | BQ18: 0 | BR18: 0 | BS18: 0 | BT18: 0 | BU18: 0 | BV18: 0 | BW18: 0 | BX18: 0 | BY18: 0 | BZ18: 0 | CA18: 0 | CB18: 0 | CC18: 0 | CD18: 0 | CE18: 0 | CF18: 0 | CG18: 0 | CH18: 0 | CI18: 0.13201595 | CJ18: 0.040293127 | CK18: 0.026721222 | CL18: 0.080538579 | CM18: 0.015936744 | CN18: 0.015481301 | CO18: 8.3497153e-07 | CP18: 2.7357811 | CQ18: 2.8497186 | CR18: 0 | CS18: 0 | CT18: 0 | CU18: 0.3102237 | CV18: 20.540912 | CW18: 55.794524 | CX18: 102.49936 | CY18: 172.28205 | CZ18: 223.59658 | DA18: 1197.0757 | DB18: 892.71176 | DC18: 746.97279 | DD18: 854.55564 | DE18: 886.92986 | DF18: 904.17465 | DG18: 909.86265 | DH18: 912.3941 | DI18: 909.58044 | DK18: 7308 | DL18: 6110.9243
