Workbook

Sheet ÍNDICE
B5: MATRIZ INSUMO-PRODUTO - 2021 (67 ATIVIDADES - PREÇOS CORRENTES)
B7: Tabela 1 - Recursos de bens e serviços
B8: Tabela 2 - Usos Totais a preços de consumidor
B9: Tabela 3 - Demanda da produção nacionais a preço básico
B10: Tabela 4 - Demanda de produtos importados a preço básico
B11: Tabela 5 - Destino dos impostos sobre produtos nacionais e importados (soma das Tabels 5 e 6 do SCN 2010, IBGE)
B12: Tabela 6 - Destino da margem de comércio sobre produtos nacionais e importados (soma das Tabels 7 e 8 do SCN 2010, IBGE)
B13: Tabela 7 - Destino da margem de transporte sobre produtos nacionais e importados (soma das Tabels 9 e 10 do SCN 2010, IBGE)
B14: Tabela 8 - Matriz dos coeficientes técnicos intersetoriais nacionais
B15: Tabela 9 - Matriz dos coeficientes técnicos intersetoriais importados
B16: Tabela 10 - Matriz de impacto intersetorial - Matriz de Leontief
B18: Referenciar como:
B19: ALVES-PASSONI, Patieene; FREITAS, Fabio. Como deflacionar matrizes insumo-produto? Uma proposta de uma série deflacionada para o Brasil no SCN 2010. Texto para Discussão, 030/2021, Instituto de Economia/IE, UFRJ. 2021. Disponível em: https://www.ie.ufrj.br/images/IE/TDS/2021/TD_IE_030_2021_PASSONI_FREITAS.pdf

Sheet Recursos
A1: Tabela 1 - Recursos de bens e serviços - 2021 (Preços correntes)
A2: Unidade de Medida: R$ 1.000.000,00
A3: Código da Atividade Nível 67 | B3: Descrição da Atividade Nível 67 | C3: Oferta de bens e serviços | L3: Produção das atividades | U3: Produção das atividades | AD3: Produção das atividades | AM3: Produção das atividades | AV3: Produção das atividades | BE3: Produção das atividades | BN3: Produção das atividades | CA3: Produção das atividades | CB3: Importação de bens e serviços (1)
C4: Oferta total a preço de consumidor | D4: Margem de comércio | E4: Margem de transporte | F4: Imposto de importação | G4: IPI | H4: ICMS | I4: Outros impostos menos subsídios | J4: Total de impostos líquidos de subsídios | K4: Oferta total a preço básico | L4: 0191 | M4: 0192 | N4: 0280 | O4: 0580 | P4: 0680 | Q4: 0791 | R4: 0792 | S4: 1091 | T4: 1092 | U4: 1093 | V4: 1100 | W4: 1200 | X4: 1300 | Y4: 1400 | Z4: 1500 | AA4: 1600 | AB4: 1700 | AC4: 1800 | AD4: 1991 | AE4: 1992 | AF4: 2091 | AG4: 2092 | AH4: 2093 | AI4: 2100 | AJ4: 2200 | AK4: 2300 | AL4: 2491 | AM4: 2492 | AN4: 2500 | AO4: 2600 | AP4: 2700 | AQ4: 2800 | AR4: 2991 | AS4: 2992 | AT4: 3000 | AU4: 3180 | AV4: 3300 | AW4: 3500 | AX4: 3680 | AY4: 4180 | AZ4: 4580 | BA4: 4900 | BB4: 5000 | BC4: 5100 | BD4: 5280 | BE4: 5500 | BF4: 5600 | BG4: 5800 | BH4: 5980 | BI4: 6100 | BJ4: 6280 | BK4: 6480 | BL4: 6800 | BM4: 6980 | BN4: 7180 | BO4: 7380 | BP4: 7700 | BQ4: 7880 | BR4: 8000 | BS4: 8400 | BT4: 8591 | BU4: 8592 | BV4: 8691 | BW4: 8692 | BX4: 9080 | BY4: 9480 | BZ4: 9700 | CA4: Total do produto
L5: Agricultura, inclusive o apoio à agricultura e a pós-colheita | M5: Pecuária, inclusive o apoio à pecuária | N5: Produção florestal; pesca e aquicultura | O5: Extração de carvão mineral e de minerais não metálicos | P5: Extração de petróleo e gás, inclusive as atividades de apoio | Q5: Extração de minério de ferro, inclusive beneficiamentos e a aglomeração | R5: Extração de minerais metálicos não ferrosos, inclusive beneficiamentos | S5: Abate e produtos de carne, inclusive os produtos do laticínio e da pesca | T5: Fabricação e refino de açúcar | U5: Outros produtos alimentares | V5: Fabricação de bebidas | W5: Fabricação de produtos do fumo | X5: Fabricação de produtos têxteis | Y5: Confecção de artefatos do vestuário e acessórios | Z5: Fabricação de calçados e de artefatos de couro | AA5: Fabricação de produtos da madeira | AB5: Fabricação de celulose, papel e produtos de papel | AC5: Impressão e reprodução de gravações | AD5: Refino de petróleo e coquerias | AE5: Fabricação de biocombustíveis | AF5: Fabricação de químicos orgânicos e inorgânicos, resinas e elastômeros | AG5: Fabricação de defensivos, desinfestantes, tintas e químicos diversos | AH5: Fabricação de produtos de limpeza, cosméticos/perfumaria e higiene pessoal | AI5: Fabricação de produtos farmoquímicos e farmacêuticos | AJ5: Fabricação de produtos de borracha e de material plástico | AK5: Fabricação de produtos de minerais não metálicos | AL5: Produção de ferro gusa/ferroligas, siderurgia e tubos de aço sem costura | AM5: Metalurgia de metais não ferosos e a fundição de metais | AN5: Fabricação de produtos de metal, exceto máquinas e equipamentos | AO5: Fabricação de equipamentos de informática, produtos eletrônicos e ópticos | AP5: Fabricação de máquinas e equipamentos elétricos | AQ5: Fabricação de máquinas e equipamentos mecânicos | AR5: Fabricação de automóveis, caminhões e ônibus, exceto peças | AS5: Fabricação de peças e acessórios para veículos automotores | AT5: Fabricação de outros equipamentos de transporte, exceto veículos automotores | AU5: Fabricação de móveis e de produtos de indústrias diversas | AV5: Manutenção, reparação e instalação de máquinas e equipamentos | AW5: Energia elétrica, gás natural e outras utilidades | AX5: Água, esgoto e gestão de resíduos | AY5: Construção | AZ5: Comércio por atacado e varejo | BA5: Transporte terrestre | BB5: Transporte aquaviário | BC5: Transporte aéreo | BD5: Armazenamento, atividades auxiliares dos transportes e correio | BE5: Alojamento | BF5: Alimentação | BG5: Edição e edição integrada à impressão | BH5: Atividades de televisão, rádio, cinema e gravação/edição de som e imagem | BI5: Telecomunicações | BJ5: Desenvolvimento de sistemas e outros serviços de informação | BK5: Intermediação financeira, seguros e previdência complementar | BL5: Atividades imobiliárias | BM5: Atividades jurídicas, contábeis, consultoria e sedes de empresas | BN5: Serviços de arquitetura, engenharia, testes/análises técnicas e P & D | BO5: Outras atividades profissionais, científicas e técnicas | BP5: Aluguéis não imobiliários e gestão de ativos de propriedade intelectual | BQ5: Outras atividades administrativas e serviços complementares | BR5: Atividades de vigilância, segurança e investigação | BS5: Administração pública, defesa e seguridade social | BT5: Educação pública | BU5: Educação privada | BV5: Saúde pública | BW5: Saúde privada | BX5: Atividades artísticas, criativas e de espetáculos | BY5: Organizações associativas e outros serviços pessoais | BZ5: Serviços domésticos
A6: 0191 | B6: Agricultura, inclusive o apoio à agricultura e a pós-colheita | C6: 906406.02 | D6: 84475.178 | E6: 16491.264 | F6: 345.45298 | G6: 101.53823 | H6: 6792.6681 | I6: 4222.2285 | J6: 11461.888 | K6: 793977.69 | L6: 721811.42 | M6: 35121.785 | N6: 2537.2217 | O6: 61.51842 | P6: 1.1610699 | Q6: 15.985026 | R6: 0 | S6: 396.34287 | T6: 171.41343 | U6: 2528.5604 | V6: 225.27517 | W6: 219.68728 | X6: 1795.1726 | Y6: 2.6284723 | Z6: 0.35085065 | AA6: 30.030951 | AB6: 1.3919555 | AC6: 0.79925413 | AD6: 0.18799358 | AE6: 73.608822 | AF6: 11.545733 | AG6: 1.3692319 | AH6: 0.28177697 | AI6: 0.44900395 | AJ6: 2.6162551 | AK6: 3.6771978 | AL6: 1.6664218 | AM6: 1.9415755 | AN6: 1.4091853 | AO6: 0.084991108 | AP6: 0.8009427 | AQ6: 0.13170808 | AR6: 0.081051123 | AS6: 0.60675771 | AT6: 0.051219807 | AU6: 4.5603799 | AV6: 0.033905816 | AW6: 7.18991 | AX6: 0.34052729 | AY6: 3002.0436 | AZ6: 405.96583 | BA6: 9.7467163 | BB6: 0.50600666 | BC6: 0.22176488 | BD6: 0.795877 | BE6: 38.732352 | BF6: 0.78799703 | BG6: 0.076548283 | BH6: 0.023077056 | BI6: 0.38330427 | BJ6: 0.30900741 | BK6: 5.1833319 | BL6: 118.71124 | BM6: 0.16829365 | BN6: 0.64334329 | BO6: 0.042214127 | BP6: 1.339595 | BQ6: 0.83696542 | BR6: 0.037711286 | BS6: 539.23097 | BT6: 0.095901889 | BU6: 0.23471054 | BV6: 0.00056285502 | BW6: 0.24990763 | BX6: 0.11482242 | BY6: 0.13564806 | BZ6: 0 | CA6: 769160 | CB6: 24817.685
A7: 0192 | B7: Pecuária, inclusive o apoio à pecuária | C7: 309970.73 | D7: 25288.404 | E7: 2182.3848 | F7: 58.314471 | G7: 75.061713 | H7: 4744.891 | I7: 3159.7606 | J7: 8038.0277 | K7: 274461.92 | L7: 35121.785 | M7: 222563.47 | N7: 3692.2261 | O7: 323.91158 | P7: 2.257212 | Q7: 29.150193 | R7: 0 | S7: 2452.7868 | T7: 66.62461 | U7: 787.12555 | V7: 279.75752 | W7: 120.63196 | X7: 836.81393 | Y7: 1.2322372 | Z7: 0.77647319 | AA7: 21.927141 | AB7: 0.81340173 | AC7: 0.46091956 | AD7: 0.10841347 | AE7: 20.188335 | AF7: 7.8707797 | AG7: 1.3074815 | AH7: 0.45142952 | AI7: 0.41035411 | AJ7: 1.4826292 | AK7: 15.211836 | AL7: 1.0578168 | AM7: 1.1949804 | AN7: 0.82259023 | AO7: 0.049013277 | AP7: 0.46189333 | AQ7: 0.07595435 | AR7: 0.046741138 | AS7: 0.34990936 | AT7: 0.029537803 | AU7: 2.1935904 | AV7: 0.020014964 | AW7: 4.1463285 | AX7: 0.1963777 | AY7: 5497.2756 | AZ7: 96.790489 | BA7: 17.580553 | BB7: 0.29180752 | BC7: 0.12788895 | BD7: 0.45897201 | BE7: 130.52953 | BF7: 0.45442774 | BG7: 0.044144409 | BH7: 0.013308241 | BI7: 0.22104663 | BJ7: 0.17820059 | BK7: 2.9891607 | BL7: 68.461464 | BM7: 0.097052781 | BN7: 0.37100779 | BO7: 0.024344343 | BP7: 0.77252715 | BQ7: 0.48266717 | BR7: 0.021747613 | BS7: 63.846503 | BT7: 0.12048814 | BU7: 0.13535455 | BV7: 0.00032459124 | BW7: 0.14411851 | BX7: 0.066216613 | BY7: 0.078226489 | BZ7: 0 | CA7: 272241 | CB7: 2220.9155
A8: 0280 | B8: Produção florestal; pesca e aquicultura | C8: 73945.687 | D8: 8002.165 | E8: 879.16787 | F8: 89.609382 | G8: 0.95910902 | H8: 3658.1609 | I8: 740.55635 | J8: 4489.2858 | K8: 60575.069 | L8: 2537.2217 | M8: 3692.2261 | N8: 47465.894 | O8: 25.694112 | P8: 0.038783309 | Q8: 2.1300456 | R8: 0 | S8: 23.495002 | T8: 4.4642044 | U8: 320.11333 | V8: 7.6584262 | W8: 0.98101925 | X8: 4.8539117 | Y8: 0.011586492 | Z8: 0.0075975123 | AA8: 5.9373806 | AB8: 0.11143831 | AC8: 0.058840795 | AD8: 0.013840018 | AE8: 4.5697123 | AF8: 0.67014336 | AG8: 0.18555402 | AH8: 0.0091351719 | AI8: 0.039795125 | AJ8: 0.13939015 | AK8: 1.2313329 | AL8: 0.12978536 | AM8: 0.14846341 | AN8: 0.11175609 | AO8: 0.0062570141 | AP8: 0.058965106 | AQ8: 0.0096963 | AR8: 0.0059669538 | AS8: 0.04466928 | AT8: 0.0037707833 | AU8: 0.047524773 | AV8: 0.0028688027 | AW8: 0.52931853 | AX8: 0.025069494 | AY8: 397.80955 | AZ8: 20.745129 | BA8: 198.90445 | BB8: 0.037252024 | BC8: 0.016326249 | BD8: 0.058592172 | BE8: 15.470529 | BF8: 0.058012051 | BG8: 0.0056354564 | BH8: 0.0016989244 | BI8: 0.028218719 | BJ8: 0.022749012 | BK8: 0.38159499 | BL8: 8.7395758 | BM8: 0.012389717 | BN8: 0.047362696 | BO8: 0.0031077885 | BP8: 0.098620487 | BQ8: 0.061617086 | BR8: 0.002776291 | BS8: 1.545399 | BT8: 0.014662833 | BU8: 0.017279304 | BV8: 4.143718e-05 | BW8: 0.018398108 | BX8: 0.0084531846 | BY8: 0.0099863603 | BZ8: 0 | CA8: 54743 | CB8: 5832.0688
A9: 0580 | B9: Extração de carvão mineral e de minerais não metálicos | C9: 62551.128 | D9: 4643.3001 | E9: 3771.6966 | F9: 51.112909 | G9: 6.1642404 | H9: 1764.5799 | I9: 555.17428 | J9: 2377.0314 | K9: 51759.1 | L9: 61.51842 | M9: 323.91158 | N9: 25.694112 | O9: 26274.217 | P9: 20.825161 | Q9: 1.4524874 | R9: 117.67863 | S9: 5.7206928 | T9: 0.18658425 | U9: 284.59871 | V9: 0.4613504 | W9: 0.026445887 | X9: 0.95401771 | Y9: 0.044688675 | Z9: 0.090109131 | AA9: 0.19662951 | AB9: 0.72468214 | AC9: 0.25718788 | AD9: 0.38102285 | AE9: 0.11566899 | AF9: 335.79294 | AG9: 36.385555 | AH9: 1.5487599 | AI9: 1.5402441 | AJ9: 8.5813058 | AK9: 1819.211 | AL9: 11.652292 | AM9: 308.04369 | AN9: 6.570851 | AO9: 0.97964062 | AP9: 3.7152266 | AQ9: 14.759996 | AR9: 0.48281006 | AS9: 4.0674004 | AT9: 0.36878286 | AU9: 3.7061277 | AV9: 9.9478128 | AW9: 2.3004177 | AX9: 0.11254061 | AY9: 0.58900985 | AZ9: 320.97699 | BA9: 0.49062924 | BB9: 0.15521677 | BC9: 0.068742441 | BD9: 0.25014691 | BE9: 0.021747741 | BF9: 0.23852562 | BG9: 0.029054176 | BH9: 0.0073610717 | BI9: 0.24624158 | BJ9: 0.78649971 | BK9: 1.6186209 | BL9: 36.413957 | BM9: 0.052524753 | BN9: 1.5483024 | BO9: 0.013285612 | BP9: 0.75490389 | BQ9: 0.26913539 | BR9: 0.013174363 | BS9: 23.526482 | BT9: 3.2339423 | BU9: 0.26529905 | BV9: 0.44019421 | BW9: 0.082664326 | BX9: 0.036003135 | BY9: 0.049175506 | BZ9: 0 | CA9: 30081 | CB9: 21678.1
A10: 0680 | B10: Extração de petróleo e gás, inclusive as atividades de apoio | C10: 464886.06 | D10: 529.94494 | E10: 1316.0515 | F10: 19.668928 | G10: 7.7416885 | H10: 169.48489 | I10: 6317.3711 | J10: 6514.2666 | K10: 456525.79 | L10: 1.1610699 | M10: 2.257212 | N10: 0.038783309 | O10: 20.825161 | P10: 366005.05 | Q10: 168.34829 | R10: 0.016420659 | S10: 0.90561326 | T10: 2.2256718 | U10: 2.7632161 | V10: 3.0186013 | W10: 0.15200345 | X10: 1.1058343 | Y10: 0.41082993 | Z10: 0.50743298 | AA10: 2.1807082 | AB10: 9.1212424 | AC10: 3.001638 | AD10: 3874.9964 | AE10: 0.49229216 | AF10: 122.33329 | AG10: 11.58188 | AH10: 2.4940661 | AI10: 2.5113714 | AJ10: 8.7751739 | AK10: 5.5627849 | AL10: 9.5539989 | AM10: 8.3210204 | AN10: 110.03566 | AO10: 19.112275 | AP10: 10.770648 | AQ10: 334.57366 | AR10: 4.9437445 | AS10: 11.457354 | AT10: 3.3794653 | AU10: 3.3463294 | AV10: 34.527075 | AW10: 25.455258 | AX10: 1.2255612 | AY10: 34998.192 | AZ10: 361.86888 | BA10: 5.3493396 | BB10: 1.7570538 | BC10: 0.77005473 | BD10: 2.9214303 | BE10: 0.23844334 | BF10: 2.7362351 | BG10: 0.29413954 | BH10: 0.080132599 | BI10: 1.9272256 | BJ10: 4.7921979 | BK10: 18.15132 | BL10: 412.206 | BM10: 0.58438164 | BN10: 10.003604 | BO10: 0.14658402 | BP10: 5.9112466 | BQ10: 2.9641722 | BR10: 0.13094839 | BS10: 18.129278 | BT10: 17.354681 | BU10: 1.8337937 | BV10: 2.3487361 | BW10: 0.89980698 | BX10: 0.39870854 | BY10: 0.47102333 | BZ10: 0 | CA10: 406701 | CB10: 49824.793
A11: 0791 | B11: Extração de minério de ferro, inclusive beneficiamentos e a aglomeração | C11: 311419.15 | D11: 27293.255 | E11: 3515.4322 | F11: 13.671903 | G11: 2.3427919 | H11: 8.8802528 | I11: 885.34166 | J11: 910.23661 | K11: 279700.23 | L11: 15.985026 | M11: 29.150193 | N11: 2.1300456 | O11: 1.4524874 | P11: 168.34829 | Q11: 275440.29 | R11: 245.42252 | S11: 1.0239194 | T11: 1.2106751 | U11: 1.304692 | V11: 0.22171541 | W11: 0.34215122 | X11: 0.32964651 | Y11: 0.36683666 | Z11: 1.4591713 | AA11: 0.28865406 | AB11: 2.4453105 | AC11: 0.17249884 | AD11: 0.01737367 | AE11: 0.1280216 | AF11: 33.162112 | AG11: 5.3191102 | AH11: 2.065801 | AI11: 5.0950622 | AJ11: 4.5524631 | AK11: 3.6073404 | AL11: 1028.4021 | AM11: 161.10516 | AN11: 5.2117809 | AO11: 11.560931 | AP11: 7.4797449 | AQ11: 140.58944 | AR11: 7.297535 | AS11: 7.661001 | AT11: 4.8173711 | AU11: 1.7593228 | AV11: 1.2050461 | AW11: 2.0229243 | AX11: 0.1603469 | AY11: 1597.306 | AZ11: 5.8871314 | BA11: 0.0945113 | BB11: 0.031043354 | BC11: 0.013605207 | BD11: 0.11307034 | BE11: 0.0042127799 | BF11: 0.048343376 | BG11: 0.096338499 | BH11: 0.0014157703 | BI11: 1.951988 | BJ11: 11.480303 | BK11: 0.81206727 | BL11: 7.2827915 | BM11: 0.010324764 | BN11: 23.206742 | BO11: 0.0025898237 | BP11: 0.40093951 | BQ11: 0.23861659 | BR11: 0.0023135759 | BS11: 38.494659 | BT11: 55.320535 | BU11: 3.3095372 | BV11: 7.5904064 | BW11: 0.11892738 | BX11: 0.0070443205 | BY11: 0.0083219669 | BZ11: 0 | CA11: 279099 | CB11: 601.22756
A12: 0792 | B12: Extração de minerais metálicos não ferrosos, inclusive beneficiamentos | C12: 42086.821 | D12: 3573.7623 | E12: 1371.6594 | F12: 18.603938 | G12: 3.442771 | H12: 33.122103 | I12: 598.88182 | J12: 654.05063 | K12: 36487.349 | L12: 0 | M12: 0 | N12: 0 | O12: 117.67863 | P12: 0.016420659 | Q12: 245.42252 | R12: 28652.189 | S12: 0.067053179 | T12: 0.035156297 | U12: 0.13907913 | V12: 0.019611152 | W12: 0.017999922 | X12: 0.66114996 | Y12: 0.018761829 | Z12: 0.077861006 | AA12: 0.012763805 | AB12: 0.60696308 | AC12: 0.0034730953 | AD12: 0.021857426 | AE12: 0.0019667848 | AF12: 47.513671 | AG12: 1.4876058 | AH12: 0.29377771 | AI12: 0.28066949 | AJ12: 6.1199924 | AK12: 25.21126 | AL12: 40.39905 | AM12: 1516.9202 | AN12: 19.213349 | AO12: 0.5887314 | AP12: 11.816399 | AQ12: 4.7968444 | AR12: 0.33848638 | AS12: 2.6072647 | AT12: 0.22417208 | AU12: 0.82598323 | AV12: 0.34575783 | AW12: 0.085196181 | AX12: 0.0074106868 | AY12: 0.0071989529 | AZ12: 8.1398957 | BA12: 0.003536053 | BB12: 0 | BC12: 0.00025284886 | BD12: 0.00069921745 | BE12: 0.00024135573 | BF12: -0.0011263267 | BG12: 0.0049618249 | BH12: 9.9607127e-05 | BI12: 0.10843265 | BJ12: 0.61420439 | BK12: 0.026255005 | BL12: 0 | BM12: 0.0003179766 | BN12: 1.2191789 | BO12: 0.00011876234 | BP12: 0.02115286 | BQ12: 0.010495502 | BR12: 0.00056699441 | BS12: 2.2494017 | BT12: 2.9399652 | BU12: 0.17590846 | BV12: 0.4033531 | BW12: 0.0055050816 | BX12: 0.00027583512 | BY12: 0.0026702372 | BZ12: 0 | CA12: 30712 | CB12: 5775.3487
A13: 1091 | B13: Abate e produtos de carne, inclusive os produtos do laticínio e da pesca | C13: 654849.15 | D13: 95816.847 | E13: 4490.6635 | F13: 359.85618 | G13: 505.35172 | H13: 42792.969 | I13: 4855.2985 | J13: 48513.475 | K13: 506028.16 | L13: 396.34287 | M13: 2452.7868 | N13: 23.495002 | O13: 5.7206928 | P13: 0.90561326 | Q13: 1.0239194 | R13: 0.067053179 | S13: 457232.94 | T13: 4.3279009 | U13: 16429.665 | V13: 320.63104 | W13: 0.66902054 | X13: 1.4760123 | Y13: 1.3037725 | Z13: 305.33544 | AA13: 1.8190545 | AB13: 4.1576187 | AC13: 2.1177038 | AD13: 1.6965763 | AE13: 186.94721 | AF13: 380.75902 | AG13: 180.94169 | AH13: 190.96496 | AI13: 140.28027 | AJ13: 10.55668 | AK13: 8.460885 | AL13: 12.404863 | AM13: 8.0618273 | AN13: 104.11553 | AO13: 11.130784 | AP13: 7.3428636 | AQ13: 16.129942 | AR13: 9.4046501 | AS13: 9.4120331 | AT13: 5.7443049 | AU13: 34.901644 | AV13: 1.2930743 | AW13: 15.273636 | AX13: 0.77629189 | AY13: 3.5362833 | AZ13: 16450.863 | BA13: 5.2028106 | BB13: 0.90025726 | BC13: 0.51642416 | BD13: 1.5638388 | BE13: 0.23850408 | BF13: 0.85906842 | BG13: 0.29251494 | BH13: 0.089067974 | BI13: 5.908533 | BJ13: 18.792705 | BK13: 9.8257439 | BL13: 211.20095 | BM13: 0.45268287 | BN13: 29.6254 | BO13: 0.13234834 | BP13: 4.8087929 | BQ13: 1.9801759 | BR13: 0.34038501 | BS13: 51.195608 | BT13: 67.747666 | BU13: 4.8327521 | BV13: 9.2781226 | BW13: 0.57123781 | BX13: 0.33723782 | BY13: 1.5283914 | BZ13: 0 | CA13: 495404 | CB13: 10624.164
A14: 1092 | B14: Fabricação e refino de açúcar | C14: 118140.27 | D14: 12665.015 | E14: 2382.5848 | F14: 40.420133 | G14: 97.313983 | H14: 5475.5959 | I14: 1969.6406 | J14: 7582.9706 | K14: 95509.697 | L14: 171.41343 | M14: 66.62461 | N14: 4.4642044 | O14: 0.18658425 | P14: 2.2256718 | Q14: 1.2106751 | R14: 0.035156297 | S14: 4.3279009 | T14: 57815.616 | U14: 3719.7621 | V14: 27.511335 | W14: 0.32702647 | X14: 0.78820896 | Y14: 0.54442848 | Z14: 1.0693348 | AA14: 1.0899594 | AB14: 9.8749337 | AC14: 1.5200074 | AD14: 0.28480346 | AE14: 30376.765 | AF14: 228.96101 | AG14: 25.949758 | AH14: 273.94282 | AI14: 7.2682037 | AJ14: 8.1107016 | AK14: 4.418418 | AL14: 4.5307005 | AM14: 4.896582 | AN14: 10.159067 | AO14: 28.649734 | AP14: 13.066153 | AQ14: 475.61473 | AR14: 8.4071718 | AS14: 14.908461 | AT14: 5.2670456 | AU14: 4.2846892 | AV14: 3.6059452 | AW14: 10.944494 | AX14: 0.55540867 | AY14: 2.6693398 | AZ14: 986.11947 | BA14: 48.248311 | BB14: 0.68916245 | BC14: 0.32710978 | BD14: 1.338424 | BE14: 0.11745816 | BF14: 0.96152888 | BG14: 0.17358325 | BH14: 0.041307807 | BI14: 2.3794449 | BJ14: 9.0742406 | BK14: 7.3841146 | BL14: 161.67797 | BM14: 0.26074244 | BN14: 16.92735 | BO14: 0.069271352 | BP14: 2.4518061 | BQ14: 1.3169002 | BR14: 0.10758833 | BS14: 28.444449 | BT14: 36.443721 | BU14: 2.5643701 | BV14: 4.9876776 | BW14: 0.40842782 | BX14: 0.18373756 | BY14: 0.44954619 | BZ14: 0 | CA14: 94655 | CB14: 854.69667
A15: 1093 | B15: Outros produtos alimentares | C15: 725169.67 | D15: 122243.99 | E15: 8325.4945 | F15: 1604.3253 | G15: 983.33624 | H15: 43704.452 | I15: 9572.4776 | J15: 55864.591 | K15: 538735.6 | L15: 2528.5604 | M15: 787.12555 | N15: 320.11333 | O15: 284.59871 | P15: 2.7632161 | Q15: 1.304692 | R15: 0.13907913 | S15: 16429.665 | T15: 3719.7621 | U15: 408482.57 | V15: 4011.3576 | W15: 1.619154 | X15: 6.2740592 | Y15: 4.7001181 | Z15: 56.007045 | AA15: 20.894831 | AB15: 89.463413 | AC15: 9.7130278 | AD15: 28.646819 | AE15: 13453.736 | AF15: 3722.2275 | AG15: 2870.1749 | AH15: 529.15379 | AI15: 1362.0272 | AJ15: 112.70491 | AK15: 46.594829 | AL15: 464.16151 | AM15: 38.61932 | AN15: 482.44636 | AO15: 37.440563 | AP15: 20.17717 | AQ15: 66.574505 | AR15: 16.381877 | AS15: 29.051377 | AT15: 10.113854 | AU15: 335.1011 | AV15: 4.785902 | AW15: 50.275357 | AX15: 2.379515 | AY15: 12.28897 | AZ15: 52202.798 | BA15: 69.142129 | BB15: 3.2285088 | BC15: 1.8716287 | BD15: 5.640095 | BE15: 0.87405778 | BF15: 2.9933773 | BG15: 0.79038821 | BH15: 0.32714718 | BI15: 16.058631 | BJ15: 35.101382 | BK15: 33.804319 | BL15: 757.41031 | BM15: 1.6480942 | BN15: 40.097251 | BO15: 0.48384625 | BP15: 16.652539 | BQ15: 6.600454 | BR15: 1.2646983 | BS15: 79.207314 | BT15: 82.546373 | BU15: 7.8376271 | BV15: 11.260809 | BW15: 1.7481445 | BX15: 1.2308135 | BY15: 5.688378 | BZ15: 0 | CA15: 513838 | CB15: 24897.596
A16: 1100 | B16: Fabricação de bebidas | C16: 182780.12 | D16: 24932.467 | E16: 2719.1392 | F16: 739.34076 | G16: 6351.438 | H16: 18688.468 | I16: 7196.2157 | J16: 32975.462 | K16: 122153.05 | L16: 225.27517 | M16: 279.75752 | N16: 7.6584262 | O16: 0.4613504 | P16: 3.0186013 | Q16: 0.22171541 | R16: 0.019611152 | S16: 320.63104 | T16: 27.511335 | U16: 4011.3576 | V16: 97187.747 | W16: 0.36637712 | X16: 2.9806755 | Y16: 1.2329641 | Z16: 0.71736583 | AA16: 5.6104837 | AB16: 12.570569 | AC16: 7.2950621 | AD16: 3.5211087 | AE16: 281.57624 | AF16: 44.656588 | AG16: 234.51164 | AH16: 7.4453256 | AI16: 30.831767 | AJ16: 27.151139 | AK16: 24.073851 | AL16: 35.798713 | AM16: 23.594036 | AN16: 344.37991 | AO16: 12.701531 | AP16: 12.267039 | AQ16: 114.23192 | AR16: 3.8198499 | AS16: 13.017665 | AT16: 1.9223475 | AU16: 6.6414815 | AV16: 2.4388308 | AW16: 59.684218 | AX16: 2.798549 | AY16: 15.545359 | AZ16: 5586.6515 | BA16: 14.780954 | BB16: 4.1504964 | BC16: 1.9630558 | BD16: 6.749333 | BE16: 0.70074099 | BF16: 5.8218786 | BG16: 0.68380352 | BH16: 0.24603135 | BI16: 6.610043 | BJ16: 8.1564419 | BK16: 42.535136 | BL16: 973.70922 | BM16: 1.5615616 | BN16: 7.2780064 | BO16: 0.41391438 | BP16: 13.416461 | BQ16: 7.1823111 | BR16: 0.63232291 | BS16: 16.374896 | BT16: 2.7442978 | BU16: 2.5108585 | BV16: 0.2979645 | BW16: 2.0538595 | BX16: 1.0989597 | BY16: 2.6337921 | BZ16: 0 | CA16: 110108 | CB16: 12045.052
A17: 1200 | B17: Fabricação de produtos do fumo | C17: 50280.054 | D17: 5127.9994 | E17: 41.063639 | F17: 28.187699 | G17: 7023.6992 | H17: 7214.5668 | I17: 968.0017 | J17: 15234.455 | K17: 29876.535 | L17: 219.68728 | M17: 120.63196 | N17: 0.98101925 | O17: 0.026445887 | P17: 0.15200345 | Q17: 0.34215122 | R17: 0.017999922 | S17: 0.66902054 | T17: 0.32702647 | U17: 1.619154 | V17: 0.36637712 | W17: 18018.108 | X17: 0.12512738 | Y17: 0.16862189 | Z17: 13.342624 | AA17: 0.12981354 | AB17: 26.68881 | AC17: 0.21396381 | AD17: 0.010536708 | AE17: 0.040445022 | AF17: 11.021097 | AG17: 2.1989401 | AH17: 0.93479956 | AI17: 2.098511 | AJ17: 1.5503062 | AK17: 1.410159 | AL17: 0.70255561 | AM17: 0.3970713 | AN17: 0.64533829 | AO17: 2.5714415 | AP17: 1.6474583 | AQ17: 13.080163 | AR17: 2.6201829 | AS17: 2.0520462 | AT17: 1.7093531 | AU17: 0.50885125 | AV17: 0.20664549 | AW17: 0.96231442 | AX17: 0.069867173 | AY17: 0.13502682 | AZ17: 140.1795 | BA17: 0.1498445 | BB17: 0.021730348 | BC17: 0.015507735 | BD17: 0.046496886 | BE17: 0.0086610315 | BF17: 0.0071839638 | BG17: 0.041766123 | BH17: 0.0033484079 | BI17: 0.92129497 | BJ17: 4.7403922 | BK17: 0.4183162 | BL17: 5.097954 | BM17: 0.014752781 | BN17: 9.1363666 | BO17: 0.0046235854 | BP17: 0.28353385 | BQ17: 0.12300202 | BR17: 0.015038371 | BS17: 15.210372 | BT17: 21.916222 | BU17: 1.3344402 | BV17: 3.0068382 | BW17: 0.051770111 | BX17: 0.011459122 | BY17: 0.069020991 | BZ17: 0 | CA17: 18653 | CB17: 11223.535
... A72: 9700 | B72: Serviços domésticos | C72: 61371 | D72: 0 | E72: 0 | F72: 0 | G72: 0 | H72: 0 | I72: 0 | J72: 0 | K72: 61371 | L72: 0 | M72: 0 | N72: 0 | O72: 0 | P72: 0 | Q72: 0 | R72: 0 | S72: 0 | T72: 0 | U72: 0 | V72: 0 | W72: 0 | X72: 0 | Y72: 0 | Z72: 0 | AA72: 0 | AB72: 0 | AC72: 0 | AD72: 0 | AE72: 0 | AF72: 0 | AG72: 0 | AH72: 0 | AI72: 0 | AJ72: 0 | AK72: 0 | AL72: 0 | AM72: 0 | AN72: 0 | AO72: 0 | AP72: 0 | AQ72: 0 | AR72: 0 | AS72: 0 | AT72: 0 | AU72: 0 | AV72: 0 | AW72: 0 | AX72: 0 | AY72: 0 | AZ72: 0 | BA72: 0 | BB72: 0 | BC72: 0 | BD72: 0 | BE72: 0 | BF72: 0 | BG72: 0 | BH72: 0 | BI72: 0 | BJ72: 0 | BK72: 0 | BL72: 0 | BM72: 0 | BN72: 0 | BO72: 0 | BP72: 0 | BQ72: 0 | BR72: 0 | BS72: 0 | BT72: 0 | BU72: 0 | BV72: 0 | BW72: 0 | BX72: 0 | BY72: 0 | BZ72: 61371 | CA72: 61371 | CB72: 0
A74: Total | C74: 19551489 | D74: -9.5154995e-12 | E74: -4.9022314e-12 | F74: 61876 | G74: 70414 | H74: 652462 | I74: 513391 | J74: 1298143 | K74: 18253346 | L74: 769160 | M74: 272241 | N74: 54743 | O74: 30081 | P74: 406701 | Q74: 279099 | R74: 30712 | S74: 495404 | T74: 94655 | U74: 513838 | V74: 110108 | W74: 18653 | X74: 82836 | Y74: 80645 | Z74: 50739 | AA74: 61516 | AB74: 156926 | AC74: 22332 | AD74: 678319 | AE74: 105728 | AF74: 353156 | AG74: 138097 | AH74: 67872 | AI74: 99278 | AJ74: 197694 | AK74: 143010 | AL74: 305615 | AM74: 121205 | AN74: 189661 | AO74: 146376 | AP74: 137668 | AQ74: 242983 | AR74: 241683 | AS74: 145523 | AT74: 50525 | AU74: 113057 | AV74: 107939 | AW74: 455696 | AX74: 107088 | AY74: 704341 | AZ74: 1668202 | BA74: 506364 | BB74: 34706 | BC74: 35749 | BD74: 188012 | BE74: 31722 | BF74: 287344 | BG74: 17626 | BH74: 46662 | BI74: 182343 | BJ74: 267495 | BK74: 717847 | BL74: 758313 | BM74: 285030 | BN74: 85091 | BO74: 146292 | BP74: 75203 | BQ74: 319061 | BR74: 46889 | BS74: 993216 | BT74: 404343 | BU74: 150446 | BV74: 279166 | BW74: 382369 | BX74: 42806 | BY74: 185302 | BZ74: 61371 | CA74: 16581873 | CB74: 1671473
A76: (1) Importação de bens e serviços líquida de ajuste CIF/FOB.

Sheet Usos
A1: Tabela 2 - Usos de bens e serviços - 2021 (Preços correntes)
A2: Unidade de Medida: R$ 1.000.000,00
A3: Código da Atividade Nível 67 | B3: Descrição da Atividade Nível 67 | C3: Consumo intermediário das atividades | L3: Consumo intermediário das atividades | U3: Consumo intermediário das atividades | AD3: Consumo intermediário das atividades | AM3: Consumo intermediário das atividades | AV3: Consumo intermediário das atividades | BE3: Consumo intermediário das atividades | BR3: Consumo intermediário das atividades | BS3: Demanda final | BZ3: Demanda Total
C4: 0191 | D4: 0192 | E4: 0280 | F4: 0580 | G4: 0680 | H4: 0791 | I4: 0792 | J4: 1091 | K4: 1092 | L4: 1093 | M4: 1100 | N4: 1200 | O4: 1300 | P4: 1400 | Q4: 1500 | R4: 1600 | S4: 1700 | T4: 1800 | U4: 1991 | V4: 1992 | W4: 2091 | X4: 2092 | Y4: 2093 | Z4: 2100 | AA4: 2200 | AB4: 2300 | AC4: 2491 | AD4: 2492 | AE4: 2500 | AF4: 2600 | AG4: 2700 | AH4: 2800 | AI4: 2991 | AJ4: 2992 | AK4: 3000 | AL4: 3180 | AM4: 3300 | AN4: 3500 | AO4: 3680 | AP4: 4180 | AQ4: 4580 | AR4: 4900 | AS4: 5000 | AT4: 5100 | AU4: 5280 | AV4: 5500 | AW4: 5600 | AX4: 5800 | AY4: 5980 | AZ4: 6100 | BA4: 6280 | BB4: 6480 | BC4: 6800 | BD4: 6980 | BE4: 7180 | BF4: 7380 | BG4: 7700 | BH4: 7880 | BI4: 8000 | BJ4: 8400 | BK4: 8591 | BL4: 8592 | BM4: 8691 | BN4: 8692 | BO4: 9080 | BP4: 9480 | BQ4: 9700 | BR4: Total do produto | BS4: Exportação de bens e serviços (1) | BT4: Consumo do governo | BU4: Consumo das ISFLSF | BV4: Consumo das famílias | BW4: Formação bruta de capital fixo | BX4: Variação de estoque | BY4: Demanda final y
C5: Agricultura, inclusive o apoio à agricultura e a pós-colheita | D5: Pecuária, inclusive o apoio à pecuária | E5: Produção florestal; pesca e aquicultura | F5: Extração de carvão mineral e de minerais não metálicos | G5: Extração de petróleo e gás, inclusive as atividades de apoio | H5: Extração de minério de ferro, inclusive beneficiamentos e a aglomeração | I5: Extração de minerais metálicos não ferrosos, inclusive beneficiamentos | J5: Abate e produtos de carne, inclusive os produtos do laticínio e da pesca | K5: Fabricação e refino de açúcar | L5: Outros produtos alimentares | M5: Fabricação de bebidas | N5: Fabricação de produtos do fumo | O5: Fabricação de produtos têxteis | P5: Confecção de artefatos do vestuário e acessórios | Q5: Fabricação de calçados e de artefatos de couro | R5: Fabricação de produtos da madeira | S5: Fabricação de celulose, papel e produtos de papel | T5: Impressão e reprodução de gravações | U5: Refino de petróleo e coquerias | V5: Fabricação de biocombustíveis | W5: Fabricação de químicos orgânicos e inorgânicos, resinas e elastômeros | X5: Fabricação de defensivos, desinfestantes, tintas e químicos diversos | Y5: Fabricação de produtos de limpeza, cosméticos/perfumaria e higiene pessoal | Z5: Fabricação de produtos farmoquímicos e farmacêuticos | AA5: Fabricação de produtos de borracha e de material plástico | AB5: Fabricação de produtos de minerais não metálicos | AC5: Produção de ferro gusa/ferroligas, siderurgia e tubos de aço sem costura | AD5: Metalurgia de metais não ferosos e a fundição de metais | AE5: Fabricação de produtos de metal, exceto máquinas e equipamentos | AF5: Fabricação de equipamentos de informática, produtos eletrônicos e ópticos | AG5: Fabricação de máquinas e equipamentos elétricos | AH5: Fabricação de máquinas e equipamentos mecânicos | AI5: Fabricação de automóveis, caminhões e ônibus, exceto peças | AJ5: Fabricação de peças e acessórios para veículos automotores | AK5: Fabricação de outros equipamentos de transporte, exceto veículos automotores | AL5: Fabricação de móveis e de produtos de indústrias diversas | AM5: Manutenção, reparação e instalação de máquinas e equipamentos | AN5: Energia elétrica, gás natural e outras utilidades | AO5: Água, esgoto e gestão de resíduos | AP5: Construção | AQ5: Comércio por atacado e varejo | AR5: Transporte terrestre | AS5: Transporte aquaviário | AT5: Transporte aéreo | AU5: Armazenamento, atividades auxiliares dos transportes e correio | AV5: Alojamento | AW5: Alimentação | AX5: Edição e edição integrada à impressão | AY5: Atividades de televisão, rádio, cinema e gravação/edição de som e imagem | AZ5: Telecomunicações | BA5: Desenvolvimento de sistemas e outros serviços de informação | BB5: Intermediação financeira, seguros e previdência complementar | BC5: Atividades imobiliárias | BD5: Atividades jurídicas, contábeis, consultoria e sedes de empresas | BE5: Serviços de arquitetura, engenharia, testes/análises técnicas e P & D | BF5: Outras atividades profissionais, científicas e técnicas | BG5: Aluguéis não imobiliários e gestão de ativos de propriedade intelectual | BH5: Outras atividades administrativas e serviços complementares | BI5: Atividades de vigilância, segurança e investigação | BJ5: Administração pública, defesa e seguridade social | BK5: Educação pública | BL5: Educação privada | BM5: Saúde pública | BN5: Saúde privada | BO5: Atividades artísticas, criativas e de espetáculos | BP5: Organizações associativas e outros serviços pessoais | BQ5: Serviços domésticos
A6: 0191 | B6: Agricultura, inclusive o apoio à agricultura e a pós-colheita | C6: 21763.314 | D6: 17112.899 | E6: 326.40662 | F6: 3.1620347 | G6: 11.247145 | H6: 19.109115 | I6: 2.682393 | J6: 15863.447 | K6: 42790.231 | L6: 193303.68 | M6: 4429.6644 | N6: 7692.6095 | O6: 14497.27 | P6: 1296.6729 | Q6: 11.638649 | R6: 163.48789 | S6: 313.14024 | T6: 0.30962663 | U6: 19.688264 | V6: 39735.053 | W6: 34.007364 | X6: 30.319622 | Y6: 5.5720956 | Z6: 40.86561 | AA6: 60.160668 | AB6: 31.534554 | AC6: 67.253879 | AD6: 41.28878 | AE6: 7.9404265 | AF6: 0.51340578 | AG6: 0.6443122 | AH6: 1.7510737 | AI6: 0.86895386 | AJ6: 0.71755076 | AK6: 0.70420744 | AL6: 24.765207 | AM6: 0.16545958 | AN6: 1.13106 | AO6: 88.148562 | AP6: 489.70524 | AQ6: 24335.471 | AR6: 2.4765859 | AS6: 0.11771577 | AT6: 0.44073394 | AU6: 20.617997 | AV6: 559.20552 | AW6: 7788.8309 | AX6: 0.2522445 | AY6: 1.1022581 | AZ6: 47.089224 | BA6: 6.237767 | BB6: 17.587587 | BC6: 20.802821 | BD6: 15.627761 | BE6: 17.623155 | BF6: 2.5334746 | BG6: 1.8762792 | BH6: 257.1969 | BI6: 0.54088568 | BJ6: 1826.3358 | BK6: 643.71859 | BL6: 114.59755 | BM6: 832.13591 | BN6: 349.22373 | BO6: 5.8969499 | BP6: 610.59416 | BQ6: 0 | BR6: 397761.9 | BS6: 288934.79 | BT6: 177.53961 | BU6: 0 | BV6: 168172.1 | BW6: 5007.4692 | BX6: 46352.209 | BY6: 508644.11 | BZ6: 906406.02
A7: 0192 | B7: Pecuária, inclusive o apoio à pecuária | C7: 2360.7092 | D7: 13282.043 | E7: 438.80011 | F7: 7.8843246 | G7: 29.24995 | H7: 34.479303 | I7: 4.9193312 | J7: 176538.76 | K7: 242.25269 | L7: 10363.856 | M7: 131.91233 | N7: 362.12402 | O7: 726.00686 | P7: 605.03346 | Q7: 11.346024 | R7: 327.14125 | S7: 545.89438 | T7: 0.5355486 | U7: 1.3893184 | V7: 474.32308 | W7: 119.11562 | X7: 14.737362 | Y7: 15.025633 | Z7: 20.13707 | AA7: 95.457877 | AB7: 148.03236 | AC7: 144.73255 | AD7: 80.792901 | AE7: 6.5297936 | AF7: 1.1352704 | AG7: 2.0774562 | AH7: 3.6271096 | AI7: 1.6803937 | AJ7: 1.6826953 | AK7: 1.0960173 | AL7: 14.65016 | AM7: 0.42699741 | AN7: 1.6685506 | AO7: 15.049298 | AP7: 986.28236 | AQ7: 879.8348 | AR7: 2.5410432 | AS7: 0.10464714 | AT7: 0.49084396 | AU7: 34.463198 | AV7: 578.05529 | AW7: 3181.6283 | AX7: 0.44475333 | AY7: 1.81705 | AZ7: 84.108436 | BA7: 10.854565 | BB7: 27.87088 | BC7: 38.83934 | BD7: 11.803109 | BE7: 22.814536 | BF7: 12.726878 | BG7: 2.5315187 | BH7: 44.24211 | BI7: 0.68820619 | BJ7: 507.44616 | BK7: 179.1148 | BL7: 36.068744 | BM7: 210.66233 | BN7: 158.81552 | BO7: 5.5628368 | BP7: 83.779411 | BQ7: 0 | BR7: 214279.9 | BS7: 13128.774 | BT7: 10.623994 | BU7: 0 | BV7: 50185.289 | BW7: 31332.458 | BX7: 1033.6845 | BY7: 95690.829 | BZ7: 309970.73
A8: 0280 | B8: Produção florestal; pesca e aquicultura | C8: 2777.9267 | D8: 2784.0452 | E8: 4512.2752 | F8: 2.6154121 | G8: 2.3158156 | H8: 2.6351451 | I8: 0.36466992 | J8: 4549.406 | K8: 1.4484283 | L8: 473.78993 | M8: 22.984987 | N8: 20.525818 | O8: 43.089871 | P8: 10.596841 | Q8: 7.1700035 | R8: 3847.9358 | S8: 6246.3106 | T8: 0.042726502 | U8: 0.11823837 | V8: 14.196616 | W8: 430.76307 | X8: 4.8145642 | Y8: 0.18822283 | Z8: 0.29995925 | AA8: 1028.5835 | AB8: 124.98758 | AC8: 1558.8024 | AD8: 5.9732383 | AE8: 10.022643 | AF8: 0.12359312 | AG8: 0.19966173 | AH8: 0.41648055 | AI8: 0.18322751 | AJ8: 0.16630926 | AK8: 0.097864775 | AL8: 3.2042458 | AM8: 0.050841502 | AN8: 0.22630631 | AO8: 1.0479283 | AP8: 1168.6602 | AQ8: 289.50085 | AR8: 0.28539583 | AS8: 0.012090688 | AT8: 0.045236979 | AU8: 2.6951149 | AV8: 70.612539 | AW8: 889.01129 | AX8: 0.052633971 | AY8: 0.19586468 | AZ8: 6.2234647 | BA8: 1.0745269 | BB8: 2.3499401 | BC8: 2.9762221 | BD8: 1.0867401 | BE8: 5.2977743 | BF8: 0.31883408 | BG8: 0.26556341 | BH8: 3.0592281 | BI8: 0.071800631 | BJ8: 192.97068 | BK8: 124.07145 | BL8: 17.899089 | BM8: 154.96757 | BN8: 31.549106 | BO8: 0.53273047 | BP8: 6.2016657 | BQ8: 0 | BR8: 31461.933 | BS8: 6688.6279 | BT8: 5.0223877 | BU8: 0 | BV8: 34559.58 | BW8: 2181.9304 | BX8: -951.40685 | BY8: 42483.754 | BZ8: 73945.687
A9: 0580 | B9: Extração de carvão mineral e de minerais não metálicos | C9: 249.79761 | D9: 1137.4064 | E9: 35.214173 | F9: 529.81219 | G9: 1072.3962 | H9: 2.6522006 | I9: 22.085726 | J9: 158.20153 | K9: 28.818489 | L9: 477.05887 | M9: 40.661769 | N9: 0.017652694 | O9: 0.72652667 | P9: 0.14011781 | Q9: 0.57799161 | R9: 0.17984183 | S9: 29.939155 | T9: 2.3963787 | U9: 101.44059 | V9: 807.67399 | W9: 6556.5997 | X9: 186.05574 | Y9: 10.198562 | Z9: 2.1930927 | AA9: 12.194856 | AB9: 10491.048 | AC9: 15847.337 | AD9: 1919.7405 | AE9: 29.941949 | AF9: 1.5358305 | AG9: 144.11792 | AH9: 20.340688 | AI9: 38.352838 | AJ9: 186.99506 | AK9: 8.3354314 | AL9: 75.807036 | AM9: 9.6435027 | AN9: 4151.1631 | AO9: 817.48558 | AP9: 11159.332 | AQ9: 174.75649 | AR9: 0.6280623 | AS9: 0.18763093 | AT9: 0.045234481 | AU9: 9.7716412 | AV9: 3.9304086 | AW9: 19.606694 | AX9: 0.097169311 | AY9: 0.13526986 | AZ9: 0.6190792 | BA9: 0.95593506 | BB9: 1.1996308 | BC9: 392.96344 | BD9: 1.4837362 | BE9: 12.523935 | BF9: 0.50758344 | BG9: 0.46377093 | BH9: 2.8566104 | BI9: 0.10947533 | BJ9: 130.75277 | BK9: 28.164628 | BL9: 1.5333608 | BM9: 19.046914 | BN9: 6.0923649 | BO9: 1.0271983 | BP9: 4.4172371 | BQ9: 0 | BR9: 57179.492 | BS9: 3941.0545 | BT9: 0.045260178 | BU9: 0 | BV9: 305.61348 | BW9: 25.265464 | BX9: 1099.657 | BY9: 5371.6357 | BZ9: 62551.128
A10: 0680 | B10: Extração de petróleo e gás, inclusive as atividades de apoio | C10: 67.626452 | D10: 45.676109 | E10: 2.857084 | F10: 5.033237 | G10: 9940.189 | H10: 1516.9024 | I10: 79.629162 | J10: 98.44333 | K10: 1.3546489 | L10: 903.48828 | M10: 188.128 | N10: 0.28513687 | O10: 155.5883 | P10: 1.2402705 | Q10: 2.9435957 | R10: 83.665141 | S10: 1032.6486 | T10: 0.69526972 | U10: 193934.67 | V10: 2.0401343 | W10: 2704.8483 | X10: 129.28253 | Y10: 36.588871 | Z10: 45.722364 | AA10: 158.74824 | AB10: 923.60665 | AC10: 575.18697 | AD10: 420.89789 | AE10: 511.75048 | AF10: 1.2653128 | AG10: 51.399009 | AH10: 187.71152 | AI10: 75.412668 | AJ10: 185.06088 | AK10: 3.644864 | AL10: 3.9501158 | AM10: 72.064558 | AN10: 30352.293 | AO10: 1628.6263 | AP10: 1898.8581 | AQ10: 289.15665 | AR10: 207.41841 | AS10: 4.9631533 | AT10: 0.33445265 | AU10: 153.59058 | AV10: 3.4530661 | AW10: 78.454894 | AX10: 0.65754673 | AY10: 1.4394632 | AZ10: 202.41202 | BA10: 8.7447584 | BB10: 13.178959 | BC10: 6.0506155 | BD10: 15.539587 | BE10: 84.989509 | BF10: 5.9122029 | BG10: 11.40374 | BH10: 21.78021 | BI10: 0.98761379 | BJ10: 3414.5232 | BK10: 39.705057 | BL10: 14.667452 | BM10: 4.3301047 | BN10: 9.242633 | BO10: 10.931864 | BP10: 42.846156 | BQ10: 0 | BR10: 252676.74 | BS10: 165144.13 | BT10: 0 | BU10: 0 | BV10: 1115.359 | BW10: 58608.187 | BX10: -12658.357 | BY10: 212209.32 | BZ10: 464886.06
A11: 0791 | B11: Extração de minério de ferro, inclusive beneficiamentos e a aglomeração | C11: 0.59468298 | D11: 1.2087742 | E11: 0.082631066 | F11: 0.17977575 | G11: 26.681913 | H11: 9060.1728 | I11: 134.0236 | J11: 1.925513 | K11: 0.10424184 | L11: 2.6549729 | M11: 0.37428293 | N11: 0.10099242 | O11: 0.21375188 | P11: 0.086831236 | Q11: 0.095647879 | R11: 0.44115074 | S11: 1.5901467 | T11: 1.3240992 | U11: 0.295459 | V11: 0.018094235 | W11: 0.60624145 | X11: 1.0080674 | Y11: 0.27164079 | Z11: 1.0262498 | AA11: 0.86208238 | AB11: 463.99709 | AC11: 68268.366 | AD11: 193.75942 | AE11: 12.835028 | AF11: 1.1007262 | AG11: 34.727108 | AH11: 68.187645 | AI11: 7.2949467 | AJ11: 13.286343 | AK11: 4.3838377 | AL11: 11.564517 | AM11: 27.942387 | AN11: 0.38476817 | AO11: 21.772745 | AP11: 216.61348 | AQ11: 5.864803 | AR11: 1.5405428 | AS11: 0.68526929 | AT11: 0.0043854348 | AU11: 10.672376 | AV11: 0.36436978 | AW11: 3.4108406 | AX11: 0.016152737 | AY11: 0.022237953 | AZ11: 25.400129 | BA11: 0.78520618 | BB11: 5.2590448 | BC11: 8.600266 | BD11: 2.0137999 | BE11: 15.729435 | BF11: 0.13182895 | BG11: 0.2176563 | BH11: 11.239392 | BI11: 0.080712117 | BJ11: 60.049152 | BK11: 2.817764 | BL11: 0.26310494 | BM11: 18.933916 | BN11: 0.172361 | BO11: 0.93233806 | BP11: 0.57970533 | BQ11: 0 | BR11: 78757.947 | BS11: 238522.42 | BT11: 0 | BU11: 0 | BV11: 18.770746 | BW11: 1812.8497 | BX11: -7692.8352 | BY11: 232661.2 | BZ11: 311419.15
A12: 0792 | B12: Extração de minerais metálicos não ferrosos, inclusive beneficiamentos | C12: 5.6514314 | D12: 1.9818869 | E12: 0.069584294 | F12: 0.063934853 | G12: 120.56938 | H12: 60.780043 | I12: 2605.3398 | J12: 12.578046 | K12: 0.229787 | L12: 23.087046 | M12: 1.5554655 | N12: 0.0063430536 | O12: 0.058896238 | P12: 0.0069516394 | Q12: 0.056094995 | R12: 0.0090763278 | S12: 13.014887 | T12: 10.551075 | U12: 0.0029115929 | V12: 0.010210761 | W12: 16.813469 | X12: 9.2345637 | Y12: 0.59245837 | Z12: 0.5292537 | AA12: 4.5743456 | AB12: 112.18417 | AC12: 4277.7152 | AD12: 14785.433 | AE12: 109.96405 | AF12: 6.8874203 | AG12: 289.7197 | AH12: 48.363477 | AI12: 26.10615 | AJ12: 127.70132 | AK12: 28.601229 | AL12: 101.58268 | AM12: 15.949668 | AN12: 0.54659874 | AO12: 4.1720047 | AP12: 106.97562 | AQ12: 1.3120497 | AR12: 0.61365405 | AS12: 0.004196379 | AT12: 0 | AU12: 0.0066549864 | AV12: 0.12634566 | AW12: 0.43489313 | AX12: 0.0018103055 | AY12: 0.0023292743 | AZ12: 0.024122209 | BA12: 0.037014298 | BB12: 0.0019529975 | BC12: 1.8097538 | BD12: 0.001677997 | BE12: 1.1873313 | BF12: 0.0025283167 | BG12: 0.012630621 | BH12: 0.086105622 | BI12: 0.0010995094 | BJ12: 0.54977154 | BK12: 0.15810954 | BL12: 0.00026919956 | BM12: 0.24944434 | BN12: 0.252943 | BO12: 0.00063718334 | BP12: 0.17295506 | BQ12: 0 | BR12: 22936.319 | BS12: 22409.989 | BT12: 0 | BU12: 0 | BV12: 13.302392 | BW12: 11.168367 | BX12: -3283.958 | BY12: 19150.502 | BZ12: 42086.821
A13: 1091 | B13: Abate e produtos de carne, inclusive os produtos do laticínio e da pesca | C13: 100.15135 | D13: 5271.5197 | E13: 54.165642 | F13: 21.054952 | G13: 21.135649 | H13: 20.601654 | I13: 2.9991927 | J13: 58615.538 | K13: 2.2509941 | L13: 6878.336 | M13: 103.56114 | N13: 0.74808011 | O13: 10.41066 | P13: 4.80142 | Q13: 2463.6265 | R13: 10.255182 | S13: 37.929292 | T13: 1.997377 | U13: 6.3263462 | V13: 2137.7703 | W13: 167.4838 | X13: 154.79643 | Y13: 5968.7316 | Z13: 41.18153 | AA13: 35.585438 | AB13: 10.001295 | AC13: 15.921528 | AD13: 5.4672649 | AE13: 179.08223 | AF13: 4.7281936 | AG13: 9.9773187 | AH13: 31.017499 | AI13: 9.4365201 | AJ13: 5.0760772 | AK13: 2.8151337 | AL13: 13.205986 | AM13: 8.2218516 | AN13: 4.9031508 | AO13: 7.0644243 | AP13: 35.494697 | AQ13: 940.63383 | AR13: 18.513919 | AS13: 0.33223777 | AT13: 0.41225361 | AU13: 8.4205233 | AV13: 926.22886 | AW13: 33859.88 | AX13: 0.91966111 | AY13: 1.8768964 | AZ13: 9.416963 | BA13: 6.0890404 | BB13: 9.2240854 | BC13: 3.7646672 | BD13: 9.919628 | BE13: 7.8685417 | BF13: 6.6879322 | BG13: 4.849547 | BH13: 8.8128326 | BI13: 1.2242711 | BJ13: 4865.8701 | BK13: 2362.9083 | BL13: 501.30878 | BM13: 3235.1781 | BN13: 1463.9684 | BO13: 13.104671 | BP13: 412.84907 | BQ13: 0 | BR13: 131155.63 | BS13: 114930.97 | BT13: 101.02011 | BU13: 0 | BV13: 406060.51 | BW13: 255.22113 | BX13: 2345.79 | BY13: 523693.51 | BZ13: 654849.15
A14: 1092 | B14: Fabricação e refino de açúcar | C14: 107.67493 | D14: 221.52063 | E14: 5.8870263 | F14: 3.1741749 | G14: 556.65548 | H14: 77.243334 | I14: 8.9053058 | J14: 715.70942 | K14: 3164.1118 | L14: 7667.4427 | M14: 1752.1188 | N14: 0.20020437 | O14: 0.87791872 | P14: 0.98358962 | Q14: 0.50347001 | R14: 58.185908 | S14: 8.7733159 | T14: 0.087717373 | U14: 18298.418 | V14: 2800.3141 | W14: 290.81823 | X14: 1001.9189 | Y14: 1178.5593 | Z14: 546.59328 | AA14: 2.5308212 | AB14: 2.555786 | AC14: 1.8815432 | AD14: 1.1445144 | AE14: 31.940838 | AF14: 1.5319163 | AG14: 7.6118447 | AH14: 222.10184 | AI14: 23.273384 | AJ14: 2.2970089 | AK14: 4.3687097 | AL14: 3.5228837 | AM14: 93.556109 | AN14: 7.8291368 | AO14: 37.84811 | AP14: 395.21957 | AQ14: 1039.2375 | AR14: 672.59226 | AS14: 11.357167 | AT14: 23.776004 | AU14: 66.289187 | AV14: 19.29053 | AW14: 1660.227 | AX14: 6.1529032 | AY14: 12.08134 | AZ14: 29.829894 | BA14: 71.985725 | BB14: 116.83295 | BC14: 24.349459 | BD14: 131.70626 | BE14: 159.79502 | BF14: 60.365467 | BG14: 155.3213 | BH14: 195.27624 | BI14: 74.174375 | BJ14: 595.74298 | BK14: 154.07611 | BL14: 24.182172 | BM14: 168.61032 | BN14: 114.4334 | BO14: 27.970079 | BP14: 177.90083 | BQ14: 0 | BR14: 45099.448 | BS14: 43445.093 | BT14: 0.034380726 | BU14: 0 | BV14: 28436.384 | BW14: 655.5277 | BX14: 503.77962 | BY14: 73040.819 | BZ14: 118140.27
A15: 1093 | B15: Outros produtos alimentares | C15: 4788.4353 | D15: 33543.216 | E15: 2505.9331 | F15: 407.55777 | G15: 427.50378 | H15: 189.43821 | I15: 35.112665 | J15: 60910.736 | K15: 78.004932 | L15: 69362.873 | M15: 5176.6393 | N15: 4.0053189 | O15: 85.246062 | P15: 37.944023 | Q15: 63.9742 | R15: 158.3019 | S15: 2098.3272 | T15: 32.828432 | U15: 6578.6252 | V15: 10760.222 | W15: 1805.8628 | X15: 2417.968 | Y15: 2249.1116 | Z15: 505.91381 | AA15: 350.08747 | AB15: 164.48257 | AC15: 184.88235 | AD15: 44.643786 | AE15: 264.46402 | AF15: 20.654924 | AG15: 72.624646 | AH15: 207.93099 | AI15: 76.542648 | AJ15: 65.539144 | AK15: 17.747662 | AL15: 122.20028 | AM15: 77.423945 | AN15: 25.636854 | AO15: 81.529179 | AP15: 468.47349 | AQ15: 8089.4699 | AR15: 316.4545 | AS15: 6.0665684 | AT15: 42.817925 | AU15: 85.48875 | AV15: 437.12695 | AW15: 23085.452 | AX15: 6.3519512 | AY15: 11.718415 | AZ15: 61.797552 | BA15: 47.097631 | BB15: 257.87737 | BC15: 49.484191 | BD15: 125.50305 | BE15: 84.831709 | BF15: 142.21393 | BG15: 80.850202 | BH15: 121.46809 | BI15: 30.949762 | BJ15: 3654.2468 | BK15: 2317.7976 | BL15: 356.05947 | BM15: 4848.9649 | BN15: 1333.9866 | BO15: 84.539402 | BP15: 1449.2713 | BQ15: 0 | BR15: 253596.53 | BS15: 77693.403 | BT15: 128.06951 | BU15: 0 | BV15: 384417.11 | BW15: 432.49348 | BX15: 8902.0646 | BY15: 471573.14 | BZ15: 725169.67
A16: 1100 | B16: Fabricação de bebidas | C16: 29.789357 | D16: 7.9365174 | E16: 0.50304841 | F16: 33.65391 | G16: 33.588506 | H16: 42.53833 | I16: 5.972537 | J16: 752.53967 | K16: 4.6220815 | L16: 179.52372 | M16: 15135.858 | N16: 0.96680965 | O16: 6.1929172 | P16: 4.8743695 | Q16: 3.9318069 | R16: 18.148816 | S16: 20.082511 | T16: 3.5172706 | U16: 62.660143 | V16: 11.240144 | W16: 27.376207 | X16: 64.754223 | Y16: 24.176303 | Z16: 21.223355 | AA16: 30.875647 | AB16: 15.064902 | AC16: 25.525583 | AD16: 3.6609027 | AE16: 58.981366 | AF16: 9.6060861 | AG16: 20.716714 | AH16: 104.08794 | AI16: 27.140103 | AJ16: 13.944417 | AK16: 8.6418463 | AL16: 16.756168 | AM16: 39.833349 | AN16: 14.553523 | AO16: 11.313155 | AP16: 127.74025 | AQ16: 401.67342 | AR16: 34.937775 | AS16: 1.273937 | AT16: 10.04534 | AU16: 27.525678 | AV16: 898.41355 | AW16: 51534.511 | AX16: 1.9005902 | AY16: 4.3774105 | AZ16: 19.609664 | BA16: 19.80799 | BB16: 151.9373 | BC16: 15.055192 | BD16: 38.899817 | BE16: 7.392457 | BF16: 11.886788 | BG16: 10.789061 | BH16: 33.577809 | BI16: 3.3481481 | BJ16: 274.89409 | BK16: 151.31601 | BL16: 47.559639 | BM16: 213.47491 | BN16: 269.39209 | BO16: 72.303747 | BP16: 39.16073 | BQ16: 0 | BR16: 71319.176 | BS16: 4450.8909 | BT16: 0.52454047 | BU16: 0 | BV16: 105256.7 | BW16: 158.65431 | BX16: 1594.1754 | BY16: 111460.95 | BZ16: 182780.12
A17: 1200 | B17: Fabricação de produtos do fumo | C17: 12.445479 | D17: 1.311102 | E17: 0.093345236 | F17: 0.029789157 | G17: 1.6259145 | H17: 2.593272 | I17: 0.20231841 | J17: 3.1026139 | K17: 0.1529166 | L17: 2.8049378 | M17: 0.30074728 | N17: 1953.1315 | O17: 0.43274466 | P17: 0.29170654 | Q17: 0.42436732 | R17: 1.0535838 | S17: 5.8479955 | T17: 0.63577308 | U17: 0.16634306 | V17: 0.15640531 | W17: 0.78139312 | X17: 0.30796561 | Y17: 0.99297294 | Z17: 1.0827888 | AA17: 1.6784622 | AB17: 1.3957584 | AC17: 0.25883577 | AD17: 0.28888867 | AE17: 0.96925641 | AF17: 0.61574008 | AG17: 0.68196543 | AH17: 6.080907 | AI17: 0.87809798 | AJ17: 0.61639666 | AK17: 0.16569873 | AL17: 0.68640026 | AM17: 2.1184511 | AN17: 0.16518914 | AO17: 0.17792177 | AP17: 1.0745092 | AQ17: 6.9000903 | AR17: 0.92364294 | AS17: 0.088726185 | AT17: 0.0072994784 | AU17: 0.43084586 | AV17: 0.11036157 | AW17: 0.76407903 | AX17: 0.42387077 | AY17: 0.13164979 | AZ17: 0.44528009 | BA17: 0.87178913 | BB17: 0.86529598 | BC17: 0.2094792 | BD17: 0.99761153 | BE17: 1.6499756 | BF17: 0.42768856 | BG17: 0.48777209 | BH17: 1.7578269 | BI17: 0.057017967 | BJ17: 0.64633811 | BK17: 0.35818905 | BL17: 0.44307928 | BM17: 0.29736913 | BN17: 0.52234689 | BO17: 0.14872013 | BP17: 0.40059235 | BQ17: 0 | BR17: 2028.1874 | BS17: 7614.007 | BT17: 0 | BU17: 0 | BV17: 40628.587 | BW17: 88.438054 | BX17: -79.166052 | BY17: 48251.866 | BZ17: 50280.054
... A72: 9700 | B72: Serviços domésticos | C72: 0 | D72: 0 | E72: 0 | F72: 0 | G72: 0 | H72: 0 | I72: 0 | J72: 0 | K72: 0 | L72: 0 | M72: 0 | N72: 0 | O72: 0 | P72: 0 | Q72: 0 | R72: 0 | S72: 0 | T72: 0 | U72: 0 | V72: 0 | W72: 0 | X72: 0 | Y72: 0 | Z72: 0 | AA72: 0 | AB72: 0 | AC72: 0 | AD72: 0 | AE72: 0 | AF72: 0 | AG72: 0 | AH72: 0 | AI72: 0 | AJ72: 0 | AK72: 0 | AL72: 0 | AM72: 0 | AN72: 0 | AO72: 0 | AP72: 0 | AQ72: 0 | AR72: 0 | AS72: 0 | AT72: 0 | AU72: 0 | AV72: 0 | AW72: 0 | AX72: 0 | AY72: 0 | AZ72: 0 | BA72: 0 | BB72: 0 | BC72: 0 | BD72: 0 | BE72: 0 | BF72: 0 | BG72: 0 | BH72: 0 | BI72: 0 | BJ72: 0 | BK72: 0 | BL72: 0 | BM72: 0 | BN72: 0 | BO72: 0 | BP72: 0 | BQ72: 0 | BR72: 0 | BS72: 0 | BT72: 0 | BU72: 0 | BV72: 61371 | BW72: 0 | BX72: 0 | BY72: 61371 | BZ72: 61371
A74: Total | C74: 348051 | D74: 141796 | E74: 15212 | F74: 18520 | G74: 174814 | H74: 111869 | I74: 16523 | J74: 435454 | K74: 75667 | L74: 435519 | M74: 83915 | N74: 15547 | O74: 63466 | P74: 51836 | Q74: 34396 | R74: 41952 | S74: 127062 | T74: 14213 | U74: 588162 | V74: 84734 | W74: 290927 | X74: 118525 | Y74: 56532 | Z74: 53734 | AA74: 160394 | AB74: 100211 | AC74: 209604 | AD74: 91739 | AE74: 138051 | AF74: 126429 | AG74: 108153 | AH74: 183858 | AI74: 216145 | AJ74: 113059 | AK74: 41613 | AL74: 68465 | AM74: 70840 | AN74: 298398 | AO74: 43404 | AP74: 429230 | AQ74: 702500 | AR74: 322829 | AS74: 20090 | AT74: 32676 | AU74: 85194 | AV74: 15307 | AW74: 166632 | AX74: 9631 | AY74: 29129 | AZ74: 103332 | BA74: 107503 | BB74: 270799 | BC74: 58848 | BD74: 89956 | BE74: 34915 | BF74: 92519 | BG74: 25361 | BH74: 105540 | BI74: 10513 | BJ74: 273272 | BK74: 64020 | BL74: 49718 | BM74: 120477 | BN74: 160147 | BO74: 19915 | BP74: 99032 | BQ74: 0 | BR74: 8867874 | BS74: 1722169 | BT74: 1671535 | BU74: 115048 | BV74: 5415523 | BW74: 1614782 | BX74: 144558 | BY74: 10683615 | BZ74: 19551489
A76: (1) Exportação de bens e serviços líquida de ajuste CIF/FOB.
A79: Valor adicionado
A80: Operações | C80: Valor adicionado | I80: Valor adicionado | Y80: Valor adicionado | AP80: Valor adicionado | BB80: Valor adicionado
C81: 0191 | D81: 0192 | E81: 0280 | F81: 0580 | G81: 0680 | H81: 0791 | I81: 0792 | J81: 1091 | K81: 1092 | L81: 1093 | M81: 1100 | N81: 1200 | O81: 1300 | P81: 1400 | Q81: 1500 | R81: 1600 | S81: 1700 | T81: 1800 | U81: 1991 | V81: 1992 | W81: 2091 | X81: 2092 | Y81: 2093 | Z81: 2100 | AA81: 2200 | AB81: 2300 | AC81: 2491 | AD81: 2492 | AE81: 2500 | AF81: 2600 | AG81: 2700 | AH81: 2800 | AI81: 2991 | AJ81: 2992 | AK81: 3000 | AL81: 3180 | AM81: 3300 | AN81: 3500 | AO81: 3680 | AP81: 4180 | AQ81: 4580 | AR81: 4900 | AS81: 5000 | AT81: 5100 | AU81: 5280 | AV81: 5500 | AW81: 5600 | AX81: 5800 | AY81: 5980 | AZ81: 6100 | BA81: 6280 | BB81: 6480 | BC81: 6800 | BD81: 6980 | BE81: 7180 | BF81: 7380 | BG81: 7700 | BH81: 7880 | BI81: 8000 | BJ81: 8400 | BK81: 8591 | BL81: 8592 | BM81: 8691 | BN81: 8692 | BO81: 9080 | BP81: 9480 | BQ81: 9700 | BR81: Total
C82: Agricultura, inclusive o apoio à agricultura e a pós-colheita | D82: Pecuária, inclusive o apoio à pecuária | E82: Produção florestal; pesca e aquicultura | F82: Extração de carvão mineral e de minerais não metálicos | G82: Extração de petróleo e gás, inclusive as atividades de apoio | H82: Extração de minério de ferro, inclusive beneficiamentos e a aglomeração | I82: Extração de minerais metálicos não ferrosos, inclusive beneficiamentos | J82: Abate e produtos de carne, inclusive os produtos do laticínio e da pesca | K82: Fabricação e refino de açúcar | L82: Outros produtos alimentares | M82: Fabricação de bebidas | N82: Fabricação de produtos do fumo | O82: Fabricação de produtos têxteis | P82: Confecção de artefatos do vestuário e acessórios | Q82: Fabricação de calçados e de artefatos de couro | R82: Fabricação de produtos da madeira | S82: Fabricação de celulose, papel e produtos de papel | T82: Impressão e reprodução de gravações | U82: Refino de petróleo e coquerias | V82: Fabricação de biocombustíveis | W82: Fabricação de químicos orgânicos e inorgânicos, resinas e elastômeros | X82: Fabricação de defensivos, desinfestantes, tintas e químicos diversos | Y82: Fabricação de produtos de limpeza, cosméticos/perfumaria e higiene pessoal | Z82: Fabricação de produtos farmoquímicos e farmacêuticos | AA82: Fabricação de produtos de borracha e de material plástico | AB82: Fabricação de produtos de minerais não metálicos | AC82: Produção de ferro gusa/ferroligas, siderurgia e tubos de aço sem costura | AD82: Metalurgia de metais não ferosos e a fundição de metais | AE82: Fabricação de produtos de metal, exceto máquinas e equipamentos | AF82: Fabricação de equipamentos de informática, produtos eletrônicos e ópticos | AG82: Fabricação de máquinas e equipamentos elétricos | AH82: Fabricação de máquinas e equipamentos mecânicos | AI82: Fabricação de automóveis, caminhões e ônibus, exceto peças | AJ82: Fabricação de peças e acessórios para veículos automotores | AK82: Fabricação de outros equipamentos de transporte, exceto veículos automotores | AL82: Fabricação de móveis e de produtos de indústrias diversas | AM82: Manutenção, reparação e instalação de máquinas e equipamentos | AN82: Energia elétrica, gás natural e outras utilidades | AO82: Água, esgoto e gestão de resíduos | AP82: Construção | AQ82: Comércio por atacado e varejo | AR82: Transporte terrestre | AS82: Transporte aquaviário | AT82: Transporte aéreo | AU82: Armazenamento, atividades auxiliares dos transportes e correio | AV82: Alojamento | AW82: Alimentação | AX82: Edição e edição integrada à impressão | AY82: Atividades de televisão, rádio, cinema e gravação/edição de som e imagem | AZ82: Telecomunicações | BA82: Desenvolvimento de sistemas e outros serviços de informação | BB82: Intermediação financeira, seguros e previdência complementar | BC82: Atividades imobiliárias | BD82: Atividades jurídicas, contábeis, consultoria e sedes de empresas | BE82: Serviços de arquitetura, engenharia, testes/análises técnicas e P & D | BF82: Outras atividades profissionais, científicas e técnicas | BG82: Aluguéis não imobiliários e gestão de ativos de propriedade intelectual | BH82: Outras atividades administrativas e serviços complementares | BI82: Atividades de vigilância, segurança e investigação | BJ82: Administração pública, defesa e seguridade social | BK82: Educação pública | BL82: Educação privada | BM82: Saúde pública | BN82: Saúde privada | BO82: Atividades artísticas, criativas e de espetáculos | BP82: Organizações associativas e outros serviços pessoais | BQ82: Serviços domésticos | BR82: 1277285
A83: Valor adicionado bruto ( PIB ) | C83: 421109 | D83: 130445 | E83: 39531 | F83: 11561 | G83: 231887 | H83: 167230 | I83: 14189 | J83: 59950 | K83: 18988 | L83: 78319 | M83: 26193 | N83: 3106 | O83: 19370 | P83: 28809 | Q83: 16343 | R83: 19564 | S83: 29864 | T83: 8119 | U83: 90157 | V83: 20994 | W83: 62229 | X83: 19572 | Y83: 11340 | Z83: 45544 | AA83: 37300 | AB83: 42799 | AC83: 96011 | AD83: 29466 | AE83: 51610 | AF83: 19947 | AG83: 29515 | AH83: 59125 | AI83: 25538 | AJ83: 32464 | AK83: 8912 | AL83: 44592 | AM83: 37099 | AN83: 157298 | AO83: 63684 | AP83: 275111 | AQ83: 965702 | AR83: 183535 | AS83: 14616 | AT83: 3073 | AU83: 102818 | AV83: 16415 | AW83: 120712 | AX83: 7995 | AY83: 17533 | AZ83: 79011 | BA83: 159992 | BB83: 447048 | BC83: 699465 | BD83: 195074 | BE83: 50176 | BF83: 53773 | BG83: 49842 | BH83: 213521 | BI83: 36376 | BJ83: 719944 | BK83: 340323 | BL83: 100728 | BM83: 158689 | BN83: 222222 | BO83: 22891 | BP83: 86270 | BQ83: 61371 | BR83: 7713999
A84: Remunerações | C84: 37950 | D84: 25160 | E84: 2882 | F84: 4882 | G84: 21242 | H84: 5777 | I84: 3331 | J84: 40203 | K84: 9426 | L84: 39201 | M84: 11397 | N84: 1988 | O84: 12601 | P84: 19120 | Q84: 10928 | R84: 8175 | S84: 16184 | T84: 5338 | U84: 12103 | V84: 8112 | W84: 15965 | X84: 11824 | Y84: 7306 | Z84: 15775 | AA84: 25874 | AB84: 23721 | AC84: 14974 | AD84: 7744 | AE84: 27076 | AF84: 10741 | AG84: 18582 | AH84: 35143 | AI84: 20439 | AJ84: 22668 | AK84: 8254 | AL84: 20315 | AM84: 18587 | AN84: 20258 | AO84: 25019 | AP84: 130162 | AQ84: 471788 | AR84: 96653 | AS84: 6472 | AT84: 6682 | AU84: 48512 | AV84: 10988 | AW84: 57472 | AX84: 6183 | AY84: 12175 | AZ84: 23331 | BA84: 81702 | BB84: 201153 | BC84: 9646 | BD84: 80109 | BE84: 24050 | BF84: 22628 | BG84: 14950 | BH84: 145387 | BI84: 32583 | BJ84: 603962 | BK84: 323126 | BL84: 87511 | BM84: 149825 | BN84: 122204 | BO84: 13514 | BP84: 44244 | BQ84: 61371 | BR84: 3534648
A85: Salários | C85: 32130 | D85: 21953 | E85: 2497 | F85: 3819 | G85: 16134 | H85: 4505 | I85: 2646 | J85: 31659 | K85: 6714 | L85: 30796 | M85: 8785 | N85: 1508 | O85: 10276 | P85: 15412 | Q85: 9104 | R85: 6732 | S85: 12680 | T85: 4388 | U85: 8760 | V85: 6140 | W85: 12076 | X85: 9101 | Y85: 5723 | Z85: 12102 | AA85: 20045 | AB85: 18923 | AC85: 11307 | AD85: 6216 | AE85: 21508 | AF85: 8468 | AG85: 14383 | AH85: 27444 | AI85: 15764 | AJ85: 18860 | AK85: 6705 | AL85: 16300 | AM85: 15342 | AN85: 14733 | AO85: 18965 | AP85: 107355 | AQ85: 373643 | AR85: 78295 | AS85: 5296 | AT85: 5574 | AU85: 37541 | AV85: 9134 | AW85: 48793 | AX85: 5210 | AY85: 10231 | AZ85: 17555 | BA85: 65562 | BB85: 153797 | BC85: 7572 | BD85: 65440 | BE85: 19296 | BF85: 18734 | BG85: 11963 | BH85: 117177 | BI85: 25808 | BJ85: 429084 | BK85: 260257 | BL85: 73352 | BM85: 122956 | BN85: 105371 | BO85: 11720 | BP85: 37798 | BQ85: 59897 | BR85: 2795014
A86: Contribuições sociais efetivas | C86: 5820 | D86: 3207 | E86: 385 | F86: 1063 | G86: 5108 | H86: 1272 | I86: 685 | J86: 8544 | K86: 2712 | L86: 8405 | M86: 2612 | N86: 480 | O86: 2325 | P86: 3708 | Q86: 1824 | R86: 1443 | S86: 3504 | T86: 950 | U86: 3343 | V86: 1972 | W86: 3889 | X86: 2723 | Y86: 1583 | Z86: 3673 | AA86: 5829 | AB86: 4798 | AC86: 3667 | AD86: 1528 | AE86: 5568 | AF86: 2273 | AG86: 4199 | AH86: 7699 | AI86: 4675 | AJ86: 3808 | AK86: 1549 | AL86: 4015 | AM86: 3245 | AN86: 5525 | AO86: 6054 | AP86: 22807 | AQ86: 98145 | AR86: 18358 | AS86: 1176 | AT86: 1108 | AU86: 10971 | AV86: 1854 | AW86: 8679 | AX86: 973 | AY86: 1944 | AZ86: 5776 | BA86: 16140 | BB86: 47356 | BC86: 2074 | BD86: 14669 | BE86: 4754 | BF86: 3894 | BG86: 2987 | BH86: 28210 | BI86: 6775 | BJ86: 88731 | BK86: 55672 | BL86: 14159 | BM86: 19588 | BN86: 16833 | BO86: 1794 | BP86: 6446 | BQ86: 1474 | BR86: 639009
A87: Previdência oficial /FGTS | C87: 5820 | D87: 3207 | E87: 385 | F87: 1053 | G87: 4097 | H87: 1223 | I87: 647 | J87: 8291 | K87: 2655 | L87: 8085 | M87: 2516 | N87: 435 | O87: 2271 | P87: 3666 | Q87: 1802 | R87: 1384 | S87: 3122 | T87: 910 | U87: 2000 | V87: 1952 | W87: 3494 | X87: 2411 | Y87: 1546 | Z87: 3417 | AA87: 5648 | AB87: 4653 | AC87: 3355 | AD87: 1443 | AE87: 5407 | AF87: 2206 | AG87: 4021 | AH87: 7342 | AI87: 4427 | AJ87: 3642 | AK87: 1454 | AL87: 3899 | AM87: 3124 | AN87: 4041 | AO87: 5385 | AP87: 22210 | AQ87: 96961 | AR87: 17574 | AS87: 1128 | AT87: 1085 | AU87: 9486 | AV87: 1807 | AW87: 8628 | AX87: 943 | AY87: 1873 | AZ87: 4576 | BA87: 15121 | BB87: 41014 | BC87: 2015 | BD87: 13441 | BE87: 4573 | BF87: 3792 | BG87: 2904 | BH87: 27696 | BI87: 6725 | BJ87: 86596 | BK87: 55338 | BL87: 14077 | BM87: 19567 | BN87: 16723 | BO87: 1741 | BP87: 6349 | BQ87: 1474 | BR87: 611853
A88: Previdência privada | C88: 0 | D88: 0 | E88: 0 | F88: 10 | G88: 1011 | H88: 49 | I88: 38 | J88: 253 | K88: 57 | L88: 320 | M88: 96 | N88: 45 | O88: 54 | P88: 42 | Q88: 22 | R88: 59 | S88: 382 | T88: 40 | U88: 1343 | V88: 20 | W88: 395 | X88: 312 | Y88: 37 | Z88: 256 | AA88: 181 | AB88: 145 | AC88: 312 | AD88: 85 | AE88: 161 | AF88: 67 | AG88: 178 | AH88: 357 | AI88: 248 | AJ88: 166 | AK88: 95 | AL88: 116 | AM88: 121 | AN88: 1484 | AO88: 669 | AP88: 597 | AQ88: 1184 | AR88: 784 | AS88: 48 | AT88: 23 | AU88: 1485 | AV88: 47 | AW88: 51 | AX88: 30 | AY88: 71 | AZ88: 1200 | BA88: 1019 | BB88: 6342 | BC88: 59 | BD88: 1228 | BE88: 181 | BF88: 102 | BG88: 83 | BH88: 514 | BI88: 50 | BJ88: 2135 | BK88: 334 | BL88: 82 | BM88: 21 | BN88: 110 | BO88: 53 | BP88: 97 | BQ88: 0 | BR88: 27156
